Workbook

Sheet PISCINAS
A1: CAMARONERA | B1: PISCINA | C1: HECTAREA
A2: CAMAGUI | B2: 1 | C2: 8.19
A3: CAMAGUI | B3: 2 | C3: 6
A4: CAMAGUI | B4: 3 | C4: 7
A5: CAMAGUI | B5: 4 | C5: 4.8
A6: CAMAGUI | B6: 5 | C6: 4.2
A7: CAMAGUI | B7: 6 | C7: 8.75
A8: CAMAGUI | B8: 8 | C8: 0.4
A9: CAMAGUI | B9: RES | C9: 1

Sheet GASTOS CAMAGUI
A1: Fecha | B1: Tipo | C1: Valor | D1: Cantidad | E1: Insumo | F1: Precio unidad
A2: 44938 | B2: Luz | C2: =82/3 -> 27.333333 | I2: diesel | J2: =2100+1.9*100+225 -> 2515
A3: 44953 | B3: Logistica | C3: 752.64 | I3: comida | J3: =200*4.3 -> 860
A4: 44930 | B4: balanceado | C4: 14707.2 | D4: 500 | E4: Balanceado Finalis ACA 35% 2.5 | F4: =C4/D4 -> 29.4144 | I4: pesca | J4: =650*4 -> 2600
A5: 44930 | B5: balanceado | C5: 1181.19 | D5: 30 | E5: Balanceado Clasico 0.8 | F5: =C5/D5 -> 39.373 | I5: bacteria | J5: 980
A6: 44930 | B6: camara | C6: 500 | I6: aquapega | J6: =30*5 -> 150
A7: 44930 | B7: diesel | C7: =2100*2 -> 4200 | D7: 1200 Galones x 2 | I7: acido | J7: =150*4 -> 600
A8: 44935 | B8: bacteria | C8: =500*1.12 -> 560 | D8: 20 | E8: Fixsoil MO Saco 45 Kilo | F8: =C8/D8 -> 28 | I8: preparacion | J8: =3.75*100+3.35*50+3.15*100+5*150+200 -> 1807.5
A9: 44935 | B9: insumo | C9: =450*1.12 -> 504 | D9: 10 | E9: nitrato sodio aleman 25kilo | F9: =C9/D9 -> 50.4 | I9: balanceado | J9: =(67000/2.2)*1.59*26/25 -> 50359.636
A10: 44935 | B10: bacteria | C10: =380*1.12 -> 425.6 | D10: 2 | E10: oxynova 1kg | F10: =C10/D10 -> 212.8 | I10: sueldo | J10: 6500
A11: 44935 | B11: insumo | C11: =200*1.12 -> 224 | D11: 10 | E11: aqua shell micro kilo | F11: =C11/D11 -> 22.4 | I11: fletes | J11: 700 | M11: paga
A12: 44935 | B12: insumo | C12: =130*1.12 -> 145.6 | D12: 2 | E12: termifish - saponina 10kg | F12: =C12/D12 -> 72.8 | I12: larva | J12: =2800*2.1+350 -> 6230 | L12: =sum(J3:J1000)-J9 -> 22527.5 | M12: 87180
A13: 44935 | B13: insumo | C13: =126*1.12 -> 141.12 | D13: 90 | E13: peroxido de hidrogeno Korea 1kg | F13: =C13/D13 -> 1.568 | I13: luz+radio | J13: 100
A14: 44931 | B14: motores | C14: 700 | E14: Gastos de aceite y mantenimiento motor | I14: motor | J14: 500 | L14: =(L12/40)/30 -> 18.772917
A15: 44952 | B15: larva | C15: 6300 | I15: insumos adicional | J15: 500
A16: 44952 | B16: transpo-larva | C16: 350 | I16: mantenimiento | J16: 1000
B17: empleados
A19: 44961 | B19: luz | C19: =135.35/3 -> 45.116667
A20: 44958 | B20: bacteria | C20: =1075*1.12 -> 1204 | D20: 43 | E20: Fixsoil MO Saco 45 Kilo | F20: =C20/D20 -> 28
A21: 44958 | B21: bacteria | C21: =950*1.12 -> 1064 | D21: 5 | E21: oxynova 1kg | F21: =C21/D21 -> 212.8
A22: 44958 | B22: insumo | C22: =450*1.12 -> 504 | D22: 45 | E22: aqua shell micro kilo | F22: =C22/D22 -> 11.2
A23: 44958 | B23: insumo | C23: =315*1.12 -> 352.8 | D23: 7 | E23: nitrato sodio aleman 25kilo | F23: =C23/D23 -> 50.4
A24: 44959 | B24: insumo | C24: 237.38 | D24: 22 | E24: Melaza de cana Peru 25kg | F24: =C24/D24 -> 10.79
A25: 44959 | B25: insumo | C25: 408 | D25: 100 | E25: Cal Chimborazo 200A 25Kg | F25: =C25/D25 -> 4.08
A26: 44985 | B26: financiero | C26: 30.24 | E26: Costo Banco Pichincha
A27: 44972 | B27: balanceado | C27: 3475 | D27: 100 | E27: Balanceado Aquaxcel mw353 1.2mm | F27: =C27/D27 -> 34.75
A28: 44980 | B28: balanceado | C28: 3505 | D28: 100 | E28: Balanceado Aquaxcel mw353 1.2mm | F28: =C28/D28 -> 35.05
A29: 44959 | B29: balanceado | C29: 1181 | D29: 30 | E29: Balanceado Clasico 0.8 | F29: =C29/D29 -> 39.366667
A30: 44966 | B30: balanceado | C30: 6000 | D30: 200 | E30: Balanceado Finalis KR2 2.0 | F30: =C30/D30 -> 30
A31: 44971 | B31: balanceado | C31: 1181.19 | D31: 30 | E31: Balanceado Clasico 0.8 | F31: =C31/D31 -> 39.373
A32: 44980 | B32: balanceado | C32: 9000 | D32: 300 | E32: Balanceado Finalis KR2 2.0 | F32: =C32/D32 -> 30
A33: 44980 | B33: balanceado | C33: 590.59 | D33: 15 | E33: Balanceado Clasico 0.8 | F33: =C33/D33 -> 39.372667
A34: 44971 | B34: material | C34: 960 | D34: 6 | E34: Viajes de piedra | F34: =C34/D34 -> 160
A35: 44967 | B35: motores | C35: 700 | E35: Gastos de aceite y mantenimiento motor
A36: 44991 | B36: luz | C36: =87.75/3 -> 29.25
A37: 44994 | B37: motores | C37: 85 | E37: Aceite de motor lancha
A38: 45012 | B38: comida | C38: 574 | E38: Gastos comida febrero y marzo
A39: 44988 | B39: balanceado | C39: 6000 | D39: 200 | E39: Balanceado Finalis KR2 2.0 | F39: =C39/D39 -> 30
A40: 44993 | B40: balanceado | C40: 9000 | D40: 300 | E40: Balanceado Finalis KR2 2.0 | F40: =C40/D40 -> 30
A41: 45002 | B41: balanceado | C41: 12000 | D41: 400 | E41: Balanceado Finalis KR2 2.0 | F41: =C41/D41 -> 30
...

Sheet PRECIOS
A1: INSUMOS | B1: CODIGO | C1: PRECIO | D1: TAMANO KG | E1: PRECIO/KG
A2: Balanceado Finalis ACA 35% 2.5 | B2: NICO FINA 2.5 | C2: =30.64*0.9825 -> 30.1038 | D2: 25 | E2: =C2/D2 -> 1.204152
A3: Balanceado Clasico 0.8 | B3: NICO CLSC 0.8 | C3: =42.11*0.9825 -> 41.373075 | D3: 25 | E3: =C3/D3 -> 1.654923
A4: Balanceado Finalis KR2 2.0 | B4: NICO FINA 2.0 | C4: =31.25*0.9825 -> 30.703125 | D4: 25 | E4: =C4/D4 -> 1.228125
A5: oxynova 1kg | C5: =AVERAGEIF('GASTOS CAMAGUI'!$E2:E10000,A5,'GASTOS CAMAGUI'!$F2:F10000) -> 212.8 | D5: 1 | E5: =C5/D5 -> 212.8
A6: aqua shell micro kilo | C6: =AVERAGEIF('GASTOS CAMAGUI'!$E3:E10001,A6,'GASTOS CAMAGUI'!$F3:F10001) -> 16.8 | D6: 1 | E6: =C6/D6 -> 16.8
A7: termifish - saponina 10kg | C7: =AVERAGEIF('GASTOS CAMAGUI'!$E4:E10002,A7,'GASTOS CAMAGUI'!$F4:F10002) -> 72.8 | D7: 10 | E7: =C7/D7 -> 7.28
A8: peroxido de hidrogeno Korea 1kg | C8: =AVERAGEIF('GASTOS CAMAGUI'!$E5:E10003,A8,'GASTOS CAMAGUI'!$F5:F10003) -> 1.568 | D8: 1 | E8: =C8/D8 -> 1.568
A9: nitrato sodio aleman 25kilo | C9: =AVERAGEIF('GASTOS CAMAGUI'!$E6:E10004,A9,'GASTOS CAMAGUI'!$F6:F10004) -> 50.4 | D9: 25 | E9: =C9/D9 -> 2.016
A10: Melaza de cana Peru 25kg | C10: =AVERAGEIF('GASTOS CAMAGUI'!$E7:E10005,A10,'GASTOS CAMAGUI'!$F7:F10005) -> 10.79 | D10: 25 | E10: =C10/D10 -> 0.4316
A11: Cal Chimborazo 200A 25Kg | C11: =AVERAGEIF('GASTOS CAMAGUI'!$E8:E10006,A11,'GASTOS CAMAGUI'!$F8:F10006) -> 4.08 | D11: 25 | E11: =C11/D11 -> 0.1632
A12: Balanceado Aquaxcel mw353 1.2mm | B12: AQXCEL 1.2 | C12: =AVERAGEIF('GASTOS CAMAGUI'!$E9:E10007,A12,'GASTOS CAMAGUI'!$F9:F10007) -> 34.95 | D12: 25 | E12: =C12/D12 -> 1.398
A13: Aquapega Atun 20kg | C13: =AVERAGEIF('GASTOS CAMAGUI'!$E10:E10008,A13,'GASTOS CAMAGUI'!$F10:F10008) -> 38 | D13: 20 | E13: =C13/D13 -> 1.9
A14: Balanceado Skretting Masterline P #5 | B14: SKR MAST | C14: 24.5 | D14: 25 | E14: =C14/D14 -> 0.98
A15: Balanceado Skretting Nature Wellness #4 | B15: SKR NW#4 | C15: 33.6 | D15: 25 | E15: =C15/D15 -> 1.344
A16: Balanceado Skretting Nature Wellness #2 | B16: SKR NW#2 | C16: 43.44 | D16: 25 | E16: =C16/D16 -> 1.7376
A17: Balanceado Skretting Nature Wellness #1 | B17: SKR NW#1 | C17: 44.33 | D17: 25 | E17: =C17/D17 -> 1.7732
A18: Balanceado Skretting Nature Wellness #1 35% | B18: SKR NW#1 35 | C18: 44.87 | D18: 25 | E18: =C18/D18 -> 1.7948
A19: Balanceado Skretting Nature Wellness #0 | B19: SKR NW#0 | C19: 45.59 | D19: 25 | E19: =C19/D19 -> 1.8236
A20: Balanceado Nicovita Qualis 2.0 35% | B20: NICO QUALIS | C20: =27.16 -> 27.16 | D20: 25 | E20: =C20/D20 -> 1.0864
A21: Balanceado Skretting Setline 35% | B21: SKR SETLINE | C21: =21.9 -> 21.9 | D21: 25 | E21: =C21/D21 -> 0.876
A22: Balanceado Clasico 1.2 | B22: NICO CLSC 1.2 | C22: =41.35 -> 41.35 | D22: 25 | E22: =C22/D22 -> 1.654
A23: Balanceado Skretting Lorica #1 | B23: SKR LORICA#1 | C23: 46.42 | D23: 25 | E23: =C23/D23 -> 1.8568
A24: Balanceado Skretting Lorica #0 | B24: SKR LORICA#0 | C24: 47.64 | D24: 25 | E24: =C24/D24 -> 1.9056
A25: Balanceado Skretting Optiline P #5 | B25: SKR OPTILINE P | C25: 27 | D25: 25 | E25: =C25/D25 -> 1.08
A26: Balanceado Skretting Lorica #5 | B26: SKR LORICA#5 | C26: 31.16 | D26: 25 | E26: =C26/D26 -> 1.2464
A27: Balanceado Skretting Lorica #4 | B27: SKR LORICA#4 | C27: 36 | D27: 25 | E27: =C27/D27 -> 1.44
A28: Balanceado Skretting Optiline E #5 | B28: SKR OPTILINE E | C28: 29.5 | D28: 25 | E28: =C28/D28 -> 1.18
A29: Balanceado Skretting Lorica #2 | B29: SKR LORICA#2 | C29: 45.55 | D29: 25 | E29: =C29/D29 -> 1.822
A30: Balanceado Skretting Masterline E #5 | B30: SKR MAST E | C30: 25.5 | D30: 25 | E30: =C30/D30 -> 1.02
A31: Balanceado Skretting Masterline E AD #5 | B31: SKR MAST E AD | C31: 25.59 | D31: 25 | E31: =C31/D31 -> 1.0236
A32: Balanceado Skretting Masterline E #4 | B32: SKR MAST#4 | C32: 30.86 | D32: 25 | E32: =C32/D32 -> 1.2344
A33: Balanceado Skretting Masterline AD #5 | B33: SKR MAST AD | C33: 25 | D33: 25 | E33: =C33/D33 -> 1
A34: Balanceado Nicovita Classic 1.2 Post | B34: NICO CLSC POST | C34: 35.49 | D34: 25 | E34: =C34/D34 -> 1.4196
... A46: Balanceado Nicovita Katal Original 05 | B46: NICO KATAL 05 | C46: 55.5 | D46: 25 | E46: =C46/D46 -> 2.22
D47: 25 | E47: =C47/D47 -> 0

Sheet GrowthFormulas
A1: DIAS | B1: POBLACION | C1: CRECIMIENTO DIARIO (g) | D1: CRECIMIENTO SEMANAL (g) | E1: CRECIMIENTO ACTUAL (g) | F1: CRECIMIENTO PROMEDIO (g)
A2: 1 | B2: 1 | C2: 0.2 | D2: =C2*7 -> 1.4 | E2: =C2 -> 0.2 | F2: =AVERAGE(D2:D92) -> 1.904
A3: 2 | B3: 0.9966666 | C3: 0.2016 | D3: =C3*7 -> 1.4112 | E3: =E2+C3 -> 0.4016 | F3: PERDIDA DIA. POBLACION
A4: 3 | B4: 0.9933332 | C4: 0.2032 | D4: =C4*7 -> 1.4224 | E4: =E3+C4 -> 0.6048
A5: 4 | B5: 0.9899998 | C5: 0.2048 | D5: =C5*7 -> 1.4336 | E5: =E4+C5 -> 0.8096 | F5: 0.33333
A6: 5 | B6: 0.9866664 | C6: 0.2064 | D6: =C6*7 -> 1.4448 | E6: =E5+C6 -> 1.016
A7: 6 | B7: 0.983333 | C7: 0.208 | D7: =C7*7 -> 1.456 | E7: =E6+C7 -> 1.224
A8: 7 | B8: 0.9799996 | C8: 0.2096 | D8: =C8*7 -> 1.4672 | E8: =E7+C8 -> 1.4336
A9: 8 | B9: 0.9766662 | C9: 0.2112 | D9: =C9*7 -> 1.4784 | E9: =E8+C9 -> 1.6448
A10: 9 | B10: 0.9733328 | C10: 0.2128 | D10: =C10*7 -> 1.4896 | E10: =E9+C10 -> 1.8576
A11: 10 | B11: 0.9699994 | C11: 0.2144 | D11: =C11*7 -> 1.5008 | E11: =E10+C11 -> 2.072
A12: 11 | B12: 0.966666 | C12: 0.216 | D12: =C12*7 -> 1.512 | E12: =E11+C12 -> 2.288
A13: 12 | B13: 0.9633326 | C13: 0.2176 | D13: =C13*7 -> 1.5232 | E13: =E12+C13 -> 2.5056
A14: 13 | B14: 0.9599992 | C14: 0.2192 | D14: =C14*7 -> 1.5344 | E14: =E13+C14 -> 2.7248
A15: 14 | B15: 0.9566658 | C15: 0.2208 | D15: =C15*7 -> 1.5456 | E15: =E14+C15 -> 2.9456
A16: 15 | B16: 0.9533324 | C16: 0.2224 | D16: =C16*7 -> 1.5568 | E16: =E15+C16 -> 3.168
A17: 16 | B17: 0.949999 | C17: 0.224 | D17: =C17*7 -> 1.568 | E17: =E16+C17 -> 3.392
... A122: 121 | B122: 0.599992 | C122: 0.392 | D122: =C122*7 -> 2.744 | E122: =E121+C122 -> 35.816

Sheet PRECIOS CAMARON
A1: ENTERO | F1: EFFICIN | G1: 0.93 | Y1: CAMAGUI | AA1: ENTERO | AD1: COLA | AH1: SEMACU | AJ1: ENTERO | AM1: COLA
A2: TALLA MAX | B2: TALLA MIN | C2: GRAMOS MAX | D2: GRAMOS MIN | E2: DIFF GRAMOS | F2: PRECIO | G2: $/KILO | H2: $/libra | I2: DON JUAN | K2: GRAMOS MIN | L2: GRAMOS MAX | M2: PRECIO | N2: DIRECCION | O2: $ CERC. | P2: BORDE | R2: GRAMOS MIN | S2: GRAMOS MAX | T2: PRECIO | U2: DIRECCION | V2: $ CERC. | W2: BORDE | Y2: PISC | Z2: PESO | AA2: DIFF BORDE | AB2: % CERC | AC2: PRECIO/KG | AD2: DIFF BORDE | AE2: % CERC | AF2: PRECIO/KG | AH2: PISC | AI2: PESO | AJ2: DIFF BORDE | AK2: % CERC | AL2: PRECIO/KG | AM2: DIFF BORDE | AN2: % CERC | AO2: PRECIO/KG
A3: 70 | B3: 80 | C3: =1000/A3 -> 14.285714 | D3: =1000/B3 -> 12.5 | E3: =C3-D3 -> 1.7857143 | F3: 2.4 | G3: =IF(I3,F3*$G$1-0.132,F3*$G$1) -> 2.232 | H3: =G3/2.2 -> 1.0145455 | I3: FALSE | K3: =$D$14 -> 7.5591076 | L3: =K3+$E$14/2 -> 8.6581267 | M3: =INDEX($G$14:$G$22,MATCH(K3,$D$14:$D$22)) -> 1.9162 | N3: 0 | O3: =INDEX($G$14:$G$22,(MATCH(K3,$D$14:$D$22)+N3)) -> 1.9162 | P3: =K3 -> 7.5591076 | R3: =$D$3 -> 12.5 | S3: =R3+$E$3/2 -> 13.392857 | T3: =INDEX($G$3:$G$8,MATCH(R3,$D$3:$D$8)) -> 2.232 | U3: 0 | V3: =INDEX($G$3:$G$8,(MATCH(R3,$D$3:$D$8)+U3)) -> 2.232 | W3: =R3 -> 12.5 | Y3: 1 | Z3: {=INDEX('PROYEC. CAMAGUI'!$J$2:$J$9,1)} -> 26.46 | AA3: =IFERROR((INDEX($W$3:$W$14,MATCH(Z3,$R$3:$R$14))-(Z3+(Z3*0.075)*INDEX($U$3:$U$14,MATCH(Z3,$R$3:$R$14))))*INDEX($U$3:$U$14,MATCH(Z3,$R$3:$R$14)),"") -> -0.5245 | AB3: =IF(AA3<0,ABS(AA3)/(Z3*0.15),0) -> 0.13214916 | AC3: =IFERROR(AB3*INDEX($V$3:$V$14,MATCH(Z3,$R$3:$R$14))+(1-AB3)*INDEX($T$3:$T$14,MATCH(Z3,$R$3:$R$14)),"") -> 2.9145506 | AD3: =IFERROR((INDEX($P$3:$P$20,MATCH(Z3,$K$3:$K$20))-(Z3+(Z3*0.075)*INDEX($N$3:$N$20,MATCH(Z3,$K$3:$K$20))))*INDEX($N$3:$N20,MATCH(Z3,$K$3:$K$20)),"") -> -1.4688613 | AE3: =IF(AD3<0,ABS(AD3)/(Z3*0.15),0) -> 0.37008346 | AF3: =IFERROR(AE3*INDEX($O$3:$O$20,MATCH(Z3,$K$3:$K$20))+(1-AE3)*INDEX($M$3:$M$20,MATCH(Z3,$K$3:$K$20)),"") -> 3.0571006 | AH3: 1 | AI3: {=INDEX('PROYEC. SEMACU'!$J$2:$J$13,1)} -> 0 | AJ3: =IFERROR((INDEX($W$3:$W$14,MATCH(AI3,$R$3:$R$14))-(AI3+(AI3*0.075)*INDEX($U$3:$U$14,MATCH(AI3,$R$3:$R$14))))*INDEX($U$3:$U$14,MATCH(AI3,$R$3:$R$14)),"") | AK3: =IF(AJ3<0,ABS(AJ3)/(AI3*0.15),0) -> 0 | AL3: =IFERROR(AK3*INDEX($V$3:$V$14,MATCH(AI3,$R$3:$R$14))+(1-AK3)*INDEX($T$3:$T$14,MATCH(AI3,$R$3:$R$14)),"") | AM3: =IFERROR((INDEX($P$3:$P$20,MATCH(AI3,$K$3:$K$20))-(AI3+(AI3*0.075)*INDEX($N$3:$N$20,MATCH(AI3,$K$3:$K$20))))*INDEX($N$3:$N21,MATCH(AI3,$K$3:$K$20)),"") | AN3: =IF(AM3<0,ABS(AM3)/(AI3*0.15),0) -> 0 | AO3: =IFERROR(AN3*INDEX($O$3:$O$20,MATCH(AI3,$K$3:$K$20))+(1-AN3)*INDEX($M$3:$M$20,MATCH(AI3,$K$3:$K$20)),"")
A4: 60 | B4: 70 | C4: =1000/A4 -> 16.666667 | D4: =1000/B4 -> 14.285714 | E4: =C4-D4 -> 2.3809524 | F4: 2.5 | G4: =IF(I4,F4*$G$1-0.132,F4*$G$1) -> 2.325 | H4: =G4/2.2 -> 1.0568182 | I4: FALSE | K4: =K3+$E$14/2 -> 8.6581267 | L4: =K4+$E$14/2 -> 9.7571459 | M4: =INDEX($G$14:$G$22,MATCH(K4,$D$14:$D$22)) -> 1.9162 | N4: 1 | O4: =INDEX($G$14:$G$22,(MATCH(K4,$D$14:$D$22)+N4)) -> 2.211 | P4: =L4 -> 9.7571459 | R4: =R3+$E$3/2 -> 13.392857 | S4: =R4+$E$3/2 -> 14.285714 | T4: =INDEX($G$3:$G$8,MATCH(R4,$D$3:$D$8)) -> 2.232 | U4: 1 | V4: =INDEX($G$3:$G$8,(MATCH(R4,$D$3:$D$8)+U4)) -> 2.325 | W4: =S4 -> 14.285714 | Y4: 2 | Z4: {=INDEX('PROYEC. CAMAGUI'!$J$2:$J$9,2)} -> 23 | AA4: =IFERROR((INDEX($W$3:$W$14,MATCH(Z4,$R$3:$R$14))-(Z4+(Z4*0.075)*INDEX($U$3:$U$14,MATCH(Z4,$R$3:$R$14))))*INDEX($U$3:$U$14,MATCH(Z4,$R$3:$R$14)),"") -> 0.275 | AB4: =IF(AA4<0,ABS(AA4)/(Z4*0.15),0) -> 0 | AC4: =IFERROR(AB4*INDEX($V$3:$V$14,MATCH(Z4,$R$3:$R$14))+(1-AB4)*INDEX($T$3:$T$14,MATCH(Z4,$R$3:$R$14)),"") -> 2.511 | AD4: =IFERROR((INDEX($P$3:$P$20,MATCH(Z4,$K$3:$K$20))-(Z4+(Z4*0.075)*INDEX($N$3:$N$20,MATCH(Z4,$K$3:$K$20))))*INDEX($N$3:$N21,MATCH(Z4,$K$3:$K$20)),"") -> -1.2784029 | AE4: =IF(AD4<0,ABS(AD4)/(Z4*0.15),0) -> 0.37055156 | AF4: =IFERROR(AE4*INDEX($O$3:$O$20,MATCH(Z4,$K$3:$K$20))+(1-AE4)*INDEX($M$3:$M$20,MATCH(Z4,$K$3:$K$20)),"") -> 2.866071 | AH4: 2 | AI4: {=INDEX('PROYEC. SEMACU'!$J$2:$J$13,2)} -> 19.37 | AJ4: =IFERROR((INDEX($W$3:$W$14,MATCH(AI4,$R$3:$R$14))-(AI4+(AI4*0.075)*INDEX($U$3:$U$14,MATCH(AI4,$R$3:$R$14))))*INDEX($U$3:$U$14,MATCH(AI4,$R$3:$R$14)),"") -> -0.82275 | AK4: =IF(AJ4<0,ABS(AJ4)/(AI4*0.15),0) -> 0.28316985 | AL4: =IFERROR(AK4*INDEX($V$3:$V$14,MATCH(AI4,$R$3:$R$14))+(1-AK4)*INDEX($T$3:$T$14,MATCH(AI4,$R$3:$R$14)),"") -> 2.4443348 | AM4: =IFERROR((INDEX($P$3:$P$20,MATCH(AI4,$K$3:$K$20))-(AI4+(AI4*0.075)*INDEX($N$3:$N$20,MATCH(AI4,$K$3:$K$20))))*INDEX($N$3:$N22,MATCH(AI4,$K$3:$K$20)),"") -> -1.4458827 | AN4: =IF(AM4<0,ABS(AM4)/(AI4*0.15),0) -> 0.49763646 | AO4: =IFERROR(AN4*INDEX($O$3:$O$20,MATCH(AI4,$K$3:$K$20))+(1-AN4)*INDEX($M$3:$M$20,MATCH(AI4,$K$3:$K$20)),"") -> 2.7269
A5: 50 | B5: 60 | C5: =1000/A5 -> 20 | D5: =1000/B5 -> 16.666667 | E5: =C5-D5 -> 3.3333333 | F5: 2.6 | G5: =IF(I5,F5*$G$1-0.132,F5*$G$1) -> 2.418 | H5: =G5/2.2 -> 1.0990909 | I5: FALSE | K5: =$D$15 -> 9.7571459 | L5: =K5+$E$15/2 -> 10.563522 | M5: =INDEX($G$14:$G$22,MATCH(K5,$D$14:$D$22)) -> 2.211 | N5: -1 | O5: =INDEX($G$14:$G$22,(MATCH(K5,$D$14:$D$22)+N5)) -> 1.9162 | P5: =L4 -> 9.7571459 | R5: =$D$4 -> 14.285714 | S5: =R5+$E$4/2 -> 15.47619 | T5: =INDEX($G$3:$G$8,MATCH(R5,$D$3:$D$8)) -> 2.325 | U5: -1 | V5: =INDEX($G$3:$G$8,(MATCH(R5,$D$3:$D$8)+U5)) -> 2.232 | W5: =S4 -> 14.285714 | Y5: 3 | Z5: {=INDEX('PROYEC. CAMAGUI'!$J$2:$J$9,3)} -> 29 | AA5: =IFERROR((INDEX($W$3:$W$14,MATCH(Z5,$R$3:$R$14))-(Z5+(Z5*0.075)*INDEX($U$3:$U$14,MATCH(Z5,$R$3:$R$14))))*INDEX($U$3:$U$14,MATCH(Z5,$R$3:$R$14)),"") -> 1.825 | AB5: =IF(AA5<0,ABS(AA5)/(Z5*0.15),0) -> 0 | AC5: =IFERROR(AB5*INDEX($V$3:$V$14,MATCH(Z5,$R$3:$R$14))+(1-AB5)*INDEX($T$3:$T$14,MATCH(Z5,$R$3:$R$14)),"") -> 2.976 | AD5: =IFERROR((INDEX($P$3:$P$20,MATCH(Z5,$K$3:$K$20))-(Z5+(Z5*0.075)*INDEX($N$3:$N$20,MATCH(Z5,$K$3:$K$20))))*INDEX($N$3:$N22,MATCH(Z5,$K$3:$K$20)),"") -> -0.15063874 | AE5: =IF(AD5<0,ABS(AD5)/(Z5*0.15),0) -> 0.034629595 | AF5: =IFERROR(AE5*INDEX($O$3:$O$20,MATCH(Z5,$K$3:$K$20))+(1-AE5)*INDEX($M$3:$M$20,MATCH(Z5,$K$3:$K$20)),"") -> 3.2325912 | AH5: 3 | AI5: {=INDEX('PROYEC. SEMACU'!$J$2:$J$13,3)} -> 20.4 | AJ5: =IFERROR((INDEX($W$3:$W$14,MATCH(AI5,$R$3:$R$14))-(AI5+(AI5*0.075)*INDEX($U$3:$U$14,MATCH(AI5,$R$3:$R$14))))*INDEX($U$3:$U$14,MATCH(AI5,$R$3:$R$14)),"") -> -1.13 | AK5: =IF(AJ5<0,ABS(AJ5)/(AI5*0.15),0) -> 0.36928105 | AL5: =IFERROR(AK5*INDEX($V$3:$V$14,MATCH(AI5,$R$3:$R$14))+(1-AK5)*INDEX($T$3:$T$14,MATCH(AI5,$R$3:$R$14)),"") -> 2.4766569 | AM5: =IFERROR((INDEX($P$3:$P$20,MATCH(AI5,$K$3:$K$20))-(AI5+(AI5*0.075)*INDEX($N$3:$N$20,MATCH(AI5,$K$3:$K$20))))*INDEX($N$3:$N23,MATCH(AI5,$K$3:$K$20)),"") -> -0.50686726 | AN5: =IF(AM5<0,ABS(AM5)/(AI5*0.15),0) -> 0.1656429 | AO5: =IFERROR(AN5*INDEX($O$3:$O$20,MATCH(AI5,$K$3:$K$20))+(1-AN5)*INDEX($M$3:$M$20,MATCH(AI5,$K$3:$K$20)),"") -> 2.7269
A6: 40 | B6: 50 | C6: =1000/A6 -> 25 | D6: =1000/B6 -> 20 | E6: =C6-D6 -> 5 | F6: 2.7 | G6: =IF(I6,F6*$G$1-0.132,F6*$G$1) -> 2.511 | H6: =G6/2.2 -> 1.1413636 | I6: FALSE | K6: =K5+$E$15/2 -> 10.563522 | L6: =K6+$E$15/2 -> 11.369897 | M6: =INDEX($G$14:$G$22,MATCH(K6,$D$14:$D$22)) -> 2.211 | N6: 1 | O6: =INDEX($G$14:$G$22,(MATCH(K6,$D$14:$D$22)+N6)) -> 2.4321 | P6: =L6 -> 11.369897 | R6: =R5+$E$4/2 -> 15.47619 | S6: =R6+$E$4/2 -> 16.666667 | T6: =INDEX($G$3:$G$8,MATCH(R6,$D$3:$D$8)) -> 2.325 | U6: 1 | V6: =INDEX($G$3:$G$8,(MATCH(R6,$D$3:$D$8)+U6)) -> 2.418 | W6: =S6 -> 16.666667 | Y6: 4 | Z6: {=INDEX('PROYEC. CAMAGUI'!$J$2:$J$9,4)} -> 30 | AA6: =IFERROR((INDEX($W$3:$W$14,MATCH(Z6,$R$3:$R$14))-(Z6+(Z6*0.075)*INDEX($U$3:$U$14,MATCH(Z6,$R$3:$R$14))))*INDEX($U$3:$U$14,MATCH(Z6,$R$3:$R$14)),"") -> 1.0833333 | AB6: =IF(AA6<0,ABS(AA6)/(Z6*0.15),0) -> 0 | AC6: =IFERROR(AB6*INDEX($V$3:$V$14,MATCH(Z6,$R$3:$R$14))+(1-AB6)*INDEX($T$3:$T$14,MATCH(Z6,$R$3:$R$14)),"") -> 2.976 | AD6: =IFERROR((INDEX($P$3:$P$20,MATCH(Z6,$K$3:$K$20))-(Z6+(Z6*0.075)*INDEX($N$3:$N$20,MATCH(Z6,$K$3:$K$20))))*INDEX($N$3:$N23,MATCH(Z6,$K$3:$K$20)),"") -> 0.77436126 | AE6: =IF(AD6<0,ABS(AD6)/(Z6*0.15),0) -> 0 | AF6: =IFERROR(AE6*INDEX($O$3:$O$20,MATCH(Z6,$K$3:$K$20))+(1-AE6)*INDEX($M$3:$M$20,MATCH(Z6,$K$3:$K$20)),"") -> 3.2428 | AH6: 4 | AI6: {=INDEX('PROYEC. SEMACU'!$J$2:$J$13,4)} -> 0 | AJ6: =IFERROR((INDEX($W$3:$W$14,MATCH(AI6,$R$3:$R$14))-(AI6+(AI6*0.075)*INDEX($U$3:$U$14,MATCH(AI6,$R$3:$R$14))))*INDEX($U$3:$U$14,MATCH(AI6,$R$3:$R$14)),"") | AK6: =IF(AJ6<0,ABS(AJ6)/(AI6*0.15),0) -> 0 | AL6: =IFERROR(AK6*INDEX($V$3:$V$14,MATCH(AI6,$R$3:$R$14))+(1-AK6)*INDEX($T$3:$T$14,MATCH(AI6,$R$3:$R$14)),"") | AM6: =IFERROR((INDEX($P$3:$P$20,MATCH(AI6,$K$3:$K$20))-(AI6+(AI6*0.075)*INDEX($N$3:$N$20,MATCH(AI6,$K$3:$K$20))))*INDEX($N$3:$N24,MATCH(AI6,$K$3:$K$20)),"") | AN6: =IF(AM6<0,ABS(AM6)/(AI6*0.15),0) -> 0 | AO6: =IFERROR(AN6*INDEX($O$3:$O$20,MATCH(AI6,$K$3:$K$20))+(1-AN6)*INDEX($M$3:$M$20,MATCH(AI6,$K$3:$K$20)),"")
A7: 30 | B7: 40 | C7: =1000/A7 -> 33.333333 | D7: =1000/B7 -> 25 | E7: =C7-D7 -> 8.3333333 | F7: 3.2 | G7: =IF(I7,F7*$G$1-0.132,F7*$G$1) -> 2.976 | H7: =G7/2.2 -> 1.3527273 | I7: FALSE | K7: =$D$16 -> 11.369897 | L7: =K7+$E$16/2 -> 12.49563 | M7: =INDEX($G$14:$G$22,MATCH(K7,$D$14:$D$22)) -> 2.4321 | N7: -1 | O7: =INDEX($G$14:$G$22,(MATCH(K7,$D$14:$D$22)+N7)) -> 2.211 | P7: =L6 -> 11.369897 | R7: =$D$5 -> 16.666667 | S7: =R7+$E$5/2 -> 18.333333 | T7: =INDEX($G$3:$G$8,MATCH(R7,$D$3:$D$8)) -> 2.418 | U7: -1 | V7: =INDEX($G$3:$G$8,(MATCH(R7,$D$3:$D$8)+U7)) -> 2.325 | W7: =S6 -> 16.666667 | Y7: 5 | Z7: {=INDEX('PROYEC. CAMAGUI'!$J$2:$J$9,5)} -> 30 | AA7: =IFERROR((INDEX($W$3:$W$14,MATCH(Z7,$R$3:$R$14))-(Z7+(Z7*0.075)*INDEX($U$3:$U$14,MATCH(Z7,$R$3:$R$14))))*INDEX($U$3:$U$14,MATCH(Z7,$R$3:$R$14)),"") -> 1.0833333 | AB7: =IF(AA7<0,ABS(AA7)/(Z7*0.15),0) -> 0 | AC7: =IFERROR(AB7*INDEX($V$3:$V$14,MATCH(Z7,$R$3:$R$14))+(1-AB7)*INDEX($T$3:$T$14,MATCH(Z7,$R$3:$R$14)),"") -> 2.976 | AD7: =IFERROR((INDEX($P$3:$P$20,MATCH(Z7,$K$3:$K$20))-(Z7+(Z7*0.075)*INDEX($N$3:$N$20,MATCH(Z7,$K$3:$K$20))))*INDEX($N$3:$N24,MATCH(Z7,$K$3:$K$20)),"") -> 0.77436126 | AE7: =IF(AD7<0,ABS(AD7)/(Z7*0.15),0) -> 0 | AF7: =IFERROR(AE7*INDEX($O$3:$O$20,MATCH(Z7,$K$3:$K$20))+(1-AE7)*INDEX($M$3:$M$20,MATCH(Z7,$K$3:$K$20)),"") -> 3.2428 | AH7: 5 | AI7: {=INDEX('PROYEC. SEMACU'!$J$2:$J$13,5)} | AJ7: =IFERROR((INDEX($W$3:$W$14,MATCH(AI7,$R$3:$R$14))-(AI7+(AI7*0.075)*INDEX($U$3:$U$14,MATCH(AI7,$R$3:$R$14))))*INDEX($U$3:$U$14,MATCH(AI7,$R$3:$R$14)),"") | AK7: =IF(AJ7<0,ABS(AJ7)/(AI7*0.15),0) -> 0 | AL7: =IFERROR(AK7*INDEX($V$3:$V$14,MATCH(AI7,$R$3:$R$14))+(1-AK7)*INDEX($T$3:$T$14,MATCH(AI7,$R$3:$R$14)),"") | AM7: =IFERROR((INDEX($P$3:$P$20,MATCH(AI7,$K$3:$K$20))-(AI7+(AI7*0.075)*INDEX($N$3:$N$20,MATCH(AI7,$K$3:$K$20))))*INDEX($N$3:$N25,MATCH(AI7,$K$3:$K$20)),"") | AN7: =IF(AM7<0,ABS(AM7)/(AI7*0.15),0) -> 0 | AO7: =IFERROR(AN7*INDEX($O$3:$O$20,MATCH(AI7,$K$3:$K$20))+(1-AN7)*INDEX($M$3:$M$20,MATCH(AI7,$K$3:$K$20)),"")
A8: 20 | B8: 30 | C8: =1000/A8 -> 50 | D8: =1000/B8 -> 33.333333 | E8: =C8-D8 -> 16.666667 | F8: 3.5 | G8: =IF(I8,F8*$G$1-0.132,F8*$G$1) -> 3.255 | H8: =G8/2.2 -> 1.4795455 | I8: FALSE | K8: =K7+$E$16/2 -> 12.49563 | L8: =K8+$E$16/2 -> 13.621362 | M8: =INDEX($G$14:$G$22,MATCH(K8,$D$14:$D$22)) -> 2.4321 | N8: 1 | O8: =INDEX($G$14:$G$22,(MATCH(K8,$D$14:$D$22)+N8)) -> 2.6532 | P8: =L8 -> 13.621362 | R8: =R7+$E$5/2 -> 18.333333 | S8: =R8+$E$5/2 -> 20 | T8: =INDEX($G$3:$G$8,MATCH(R8,$D$3:$D$8)) -> 2.418 | U8: 1 | V8: =INDEX($G$3:$G$8,(MATCH(R8,$D$3:$D$8)+U8)) -> 2.511 | W8: =S8 -> 20 | Y8: 6 | Z8: {=INDEX('PROYEC. CAMAGUI'!$J$2:$J$9,6)} -> 29 | AA8: =IFERROR((INDEX($W$3:$W$14,MATCH(Z8,$R$3:$R$14))-(Z8+(Z8*0.075)*INDEX($U$3:$U$14,MATCH(Z8,$R$3:$R$14))))*INDEX($U$3:$U$14,MATCH(Z8,$R$3:$R$14)),"") -> 1.825 | AB8: =IF(AA8<0,ABS(AA8)/(Z8*0.15),0) -> 0 | AC8: =IFERROR(AB8*INDEX($V$3:$V$14,MATCH(Z8,$R$3:$R$14))+(1-AB8)*INDEX($T$3:$T$14,MATCH(Z8,$R$3:$R$14)),"") -> 2.976 | AD8: =IFERROR((INDEX($P$3:$P$20,MATCH(Z8,$K$3:$K$20))-(Z8+(Z8*0.075)*INDEX($N$3:$N$20,MATCH(Z8,$K$3:$K$20))))*INDEX($N$3:$N25,MATCH(Z8,$K$3:$K$20)),"") -> -0.15063874 | AE8: =IF(AD8<0,ABS(AD8)/(Z8*0.15),0) -> 0.034629595 | AF8: =IFERROR(AE8*INDEX($O$3:$O$20,MATCH(Z8,$K$3:$K$20))+(1-AE8)*INDEX($M$3:$M$20,MATCH(Z8,$K$3:$K$20)),"") -> 3.2325912 | AH8: 6 | AI8: {=INDEX('PROYEC. SEMACU'!$J$2:$J$13,6)} -> 0 | AJ8: =IFERROR((INDEX($W$3:$W$14,MATCH(AI8,$R$3:$R$14))-(AI8+(AI8*0.075)*INDEX($U$3:$U$14,MATCH(AI8,$R$3:$R$14))))*INDEX($U$3:$U$14,MATCH(AI8,$R$3:$R$14)),"") | AK8: =IF(AJ8<0,ABS(AJ8)/(AI8*0.15),0) -> 0 | AL8: =IFERROR(AK8*INDEX($V$3:$V$14,MATCH(AI8,$R$3:$R$14))+(1-AK8)*INDEX($T$3:$T$14,MATCH(AI8,$R$3:$R$14)),"") | AM8: =IFERROR((INDEX($P$3:$P$20,MATCH(AI8,$K$3:$K$20))-(AI8+(AI8*0.075)*INDEX($N$3:$N$20,MATCH(AI8,$K$3:$K$20))))*INDEX($N$3:$N26,MATCH(AI8,$K$3:$K$20)),"") | AN8: =IF(AM8<0,ABS(AM8)/(AI8*0.15),0) -> 0 | AO8: =IFERROR(AN8*INDEX($O$3:$O$20,MATCH(AI8,$K$3:$K$20))+(1-AN8)*INDEX($M$3:$M$20,MATCH(AI8,$K$3:$K$20)),"")
K9: =D17 -> 13.621362 | L9: =K9+$E$17/2 -> 15.303012 | M9: =INDEX($G$14:$G$22,MATCH(K9,$D$14:$D$22)) -> 2.6532 | N9: -1 | O9: =INDEX($G$14:$G$22,(MATCH(K9,$D$14:$D$22)+N9)) -> 2.4321 | P9: =L8 -> 13.621362 | R9: =$D$6 -> 20 | S9: =R9+$E$6/2 -> 22.5 | T9: =INDEX($G$3:$G$8,MATCH(R9,$D$3:$D$8)) -> 2.511 | U9: -1 | V9: =INDEX($G$3:$G$8,(MATCH(R9,$D$3:$D$8)+U9)) -> 2.418 | W9: =S8 -> 20 | Y9: 8 | Z9: {=INDEX('PROYEC. CAMAGUI'!$J$2:$J$9,6)} -> 29 | AA9: =IFERROR((INDEX($W$3:$W$14,MATCH(Z9,$R$3:$R$14))-(Z9+(Z9*0.075)*INDEX($U$3:$U$14,MATCH(Z9,$R$3:$R$14))))*INDEX($U$3:$U$14,MATCH(Z9,$R$3:$R$14)),"") -> 1.825 | AB9: =IF(AA9<0,ABS(AA9)/(Z9*0.15),0) -> 0 | AC9: =IFERROR(AB9*INDEX($V$3:$V$14,MATCH(Z9,$R$3:$R$14))+(1-AB9)*INDEX($T$3:$T$14,MATCH(Z9,$R$3:$R$14)),"") -> 2.976 | AD9: =IFERROR((INDEX($P$3:$P$20,MATCH(Z9,$K$3:$K$20))-(Z9+(Z9*0.075)*INDEX($N$3:$N$20,MATCH(Z9,$K$3:$K$20))))*INDEX($N$3:$N26,MATCH(Z9,$K$3:$K$20)),"") -> -0.15063874 | AE9: =IF(AD9<0,ABS(AD9)/(Z9*0.15),0) -> 0.034629595 | AF9: =IFERROR(AE9*INDEX($O$3:$O$20,MATCH(Z9,$K$3:$K$20))+(1-AE9)*INDEX($M$3:$M$20,MATCH(Z9,$K$3:$K$20)),"") -> 3.2325912 | AH9: 7 | AI9: {=INDEX('PROYEC. SEMACU'!$J$2:$J$13,7)} -> 0 | AJ9: =IFERROR((INDEX($W$3:$W$14,MATCH(AI9,$R$3:$R$14))-(AI9+(AI9*0.075)*INDEX($U$3:$U$14,MATCH(AI9,$R$3:$R$14))))*INDEX($U$3:$U$14,MATCH(AI9,$R$3:$R$14)),"") | AK9: =IF(AJ9<0,ABS(AJ9)/(AI9*0.15),0) -> 0 | AL9: =IFERROR(AK9*INDEX($V$3:$V$14,MATCH(AI9,$R$3:$R$14))+(1-AK9)*INDEX($T$3:$T$14,MATCH(AI9,$R$3:$R$14)),"") | AM9: =IFERROR((INDEX($P$3:$P$20,MATCH(AI9,$K$3:$K$20))-(AI9+(AI9*0.075)*INDEX($N$3:$N$20,MATCH(AI9,$K$3:$K$20))))*INDEX($N$3:$N27,MATCH(AI9,$K$3:$K$20)),"") | AN9: =IF(AM9<0,ABS(AM9)/(AI9*0.15),0) -> 0 | AO9: =IFERROR(AN9*INDEX($O$3:$O$20,MATCH(AI9,$K$3:$K$20))+(1-AN9)*INDEX($M$3:$M$20,MATCH(AI9,$K$3:$K$20)),"")
K10: =K9+$E$17/2 -> 15.303012 | L10: =K10+$E$17/2 -> 16.984661 | M10: =INDEX($G$14:$G$22,MATCH(K10,$D$14:$D$22)) -> 2.6532 | N10: 1 | O10: =INDEX($G$14:$G$22,(MATCH(K10,$D$14:$D$22)+N10)) -> 2.7269 | P10: =L10 -> 16.984661 | R10: =R9+$E$6/2 -> 22.5 | S10: =R10+$E$6/2 -> 25 | T10: =INDEX($G$3:$G$8,MATCH(R10,$D$3:$D$8)) -> 2.511 | U10: 1 | V10: =INDEX($G$3:$G$8,(MATCH(R10,$D$3:$D$8)+U10)) -> 2.976 | W10: =S10 -> 25 | Y10: RES | Z10: {=INDEX('PROYEC. CAMAGUI'!$J$2:$J$9,8)} -> 0 | AA10: =IFERROR((INDEX($W$3:$W$14,MATCH(Z10,$R$3:$R$14))-(Z10+(Z10*0.075)*INDEX($U$3:$U$14,MATCH(Z10,$R$3:$R$14))))*INDEX($U$3:$U$14,MATCH(Z10,$R$3:$R$14)),"") | AB10: =IF(AA10<0,ABS(AA10)/(Z10*0.15),0) -> 0 | AC10: =IFERROR(AB10*INDEX($V$3:$V$14,MATCH(Z10,$R$3:$R$14))+(1-AB10)*INDEX($T$3:$T$14,MATCH(Z10,$R$3:$R$14)),"") | AD10: =IFERROR((INDEX($P$3:$P$20,MATCH(Z10,$K$3:$K$20))-(Z10+(Z10*0.075)*INDEX($N$3:$N$20,MATCH(Z10,$K$3:$K$20))))*INDEX($N$3:$N27,MATCH(Z10,$K$3:$K$20)),"") | AE10: =IF(AD10<0,ABS(AD10)/(Z10*0.15),0) -> 0 | AF10: =IFERROR(AE10*INDEX($O$3:$O$20,MATCH(Z10,$K$3:$K$20))+(1-AE10)*INDEX($M$3:$M$20,MATCH(Z10,$K$3:$K$20)),"") | AH10: 8 | AI10: {=INDEX('PROYEC. SEMACU'!$J$2:$J$13,8)} -> 0 | AJ10: =IFERROR((INDEX($W$3:$W$14,MATCH(AI10,$R$3:$R$14))-(AI10+(AI10*0.075)*INDEX($U$3:$U$14,MATCH(AI10,$R$3:$R$14))))*INDEX($U$3:$U$14,MATCH(AI10,$R$3:$R$14)),"") | AK10: =IF(AJ10<0,ABS(AJ10)/(AI10*0.15),0) -> 0 | AL10: =IFERROR(AK10*INDEX($V$3:$V$14,MATCH(AI10,$R$3:$R$14))+(1-AK10)*INDEX($T$3:$T$14,MATCH(AI10,$R$3:$R$14)),"") | AM10: =IFERROR((INDEX($P$3:$P$20,MATCH(AI10,$K$3:$K$20))-(AI10+(AI10*0.075)*INDEX($N$3:$N$20,MATCH(AI10,$K$3:$K$20))))*INDEX($N$3:$N28,MATCH(AI10,$K$3:$K$20)),"") | AN10: =IF(AM10<0,ABS(AM10)/(AI10*0.15),0) -> 0 | AO10: =IFERROR(AN10*INDEX($O$3:$O$20,MATCH(AI10,$K$3:$K$20))+(1-AN10)*INDEX($M$3:$M$20,MATCH(AI10,$K$3:$K$20)),"")
K11: =D18 -> 16.984661 | L11: =K11+$E$18/2 -> 18.180764 | M11: =INDEX($G$14:$G$22,MATCH(K11,$D$14:$D$22)) -> 2.7269 | N11: -1 | O11: =INDEX($G$14:$G$22,(MATCH(K11,$D$14:$D$22)+N11)) -> 2.6532 | P11: =L10 -> 16.984661 | R11: =$D$7 -> 25 | S11: =R11+$E$7/2 -> 29.166667 | T11: =INDEX($G$3:$G$8,MATCH(R11,$D$3:$D$8)) -> 2.976 | U11: -1 | V11: =INDEX($G$3:$G$8,(MATCH(R11,$D$3:$D$8)+U11)) -> 2.511 | W11: =S10 -> 25 | AH11: 9 | AI11: {=INDEX('PROYEC. SEMACU'!$J$2:$J$13,9)} -> 0 | AJ11: =IFERROR((INDEX($W$3:$W$14,MATCH(AI11,$R$3:$R$14))-(AI11+(AI11*0.075)*INDEX($U$3:$U$14,MATCH(AI11,$R$3:$R$14))))*INDEX($U$3:$U$14,MATCH(AI11,$R$3:$R$14)),"") | AK11: =IF(AJ11<0,ABS(AJ11)/(AI11*0.15),0) -> 0 | AL11: =IFERROR(AK11*INDEX($V$3:$V$14,MATCH(AI11,$R$3:$R$14))+(1-AK11)*INDEX($T$3:$T$14,MATCH(AI11,$R$3:$R$14)),"") | AM11: =IFERROR((INDEX($P$3:$P$20,MATCH(AI11,$K$3:$K$20))-(AI11+(AI11*0.075)*INDEX($N$3:$N$20,MATCH(AI11,$K$3:$K$20))))*INDEX($N$3:$N29,MATCH(AI11,$K$3:$K$20)),"") | AN11: =IF(AM11<0,ABS(AM11)/(AI11*0.15),0) -> 0 | AO11: =IFERROR(AN11*INDEX($O$3:$O$20,MATCH(AI11,$K$3:$K$20))+(1-AN11)*INDEX($M$3:$M$20,MATCH(AI11,$K$3:$K$20)),"")
A12: COLA | H12: EFFICIENCIA | I12: 0.67 | K12: =K11+$E$18/2 -> 18.180764 | L12: =K12+$E$18/2 -> 19.376867 | M12: =INDEX($G$14:$G$22,MATCH(K12,$D$14:$D$22)) -> 2.7269 | N12: 1 | O12: =INDEX($G$14:$G$22,(MATCH(K12,$D$14:$D$22)+N12)) -> 2.7269 | P12: =L12 -> 19.376867 | R12: =R11+$E$7/2 -> 29.166667 | S12: =R12+$E$7/2 -> 33.333333 | T12: =INDEX($G$3:$G$8,MATCH(R12,$D$3:$D$8)) -> 2.976 | U12: 1 | V12: =INDEX($G$3:$G$8,(MATCH(R12,$D$3:$D$8)+U12)) -> 3.255 | W12: =S12 -> 33.333333 | AH12: 10 | AI12: {=INDEX('PROYEC. SEMACU'!$J$2:$J$13,10)} -> 0 | AJ12: =IFERROR((INDEX($W$3:$W$14,MATCH(AI12,$R$3:$R$14))-(AI12+(AI12*0.075)*INDEX($U$3:$U$14,MATCH(AI12,$R$3:$R$14))))*INDEX($U$3:$U$14,MATCH(AI12,$R$3:$R$14)),"") | AK12: =IF(AJ12<0,ABS(AJ12)/(AI12*0.15),0) -> 0 | AL12: =IFERROR(AK12*INDEX($V$3:$V$14,MATCH(AI12,$R$3:$R$14))+(1-AK12)*INDEX($T$3:$T$14,MATCH(AI12,$R$3:$R$14)),"") | AM12: =IFERROR((INDEX($P$3:$P$20,MATCH(AI12,$K$3:$K$20))-(AI12+(AI12*0.075)*INDEX($N$3:$N$20,MATCH(AI12,$K$3:$K$20))))*INDEX($N$3:$N30,MATCH(AI12,$K$3:$K$20)),"") | AN12: =IF(AM12<0,ABS(AM12)/(AI12*0.15),0) -> 0 | AO12: =IFERROR(AN12*INDEX($O$3:$O$20,MATCH(AI12,$K$3:$K$20))+(1-AN12)*INDEX($M$3:$M$20,MATCH(AI12,$K$3:$K$20)),"")
A13: TALLA MAX | B13: TALLA MIN | C13: GRAMOS MAX | D13: GRAMOS MIN | E13: DIFF GRAMOS | F13: PRECIO lb | G13: $/KILO | H13: $/libra | I13: DON JUAN | K13: =D19 -> 19.376867 | L13: =K13+$E$19/2 -> 20.965135 | M13: =INDEX($G$14:$G$22,MATCH(K13,$D$14:$D$22)) -> 2.7269 | N13: -1 | O13: =INDEX($G$14:$G$22,(MATCH(K13,$D$14:$D$22)+N13)) -> 2.7269 | P13: =L12 -> 19.376867 | R13: =$D$8 -> 33.333333 | S13: =R13+$E$8/2 -> 41.666667 | T13: =INDEX($G$3:$G$8,MATCH(R13,$D$3:$D$8)) -> 3.255 | U13: -1 | V13: =INDEX($G$3:$G$8,(MATCH(R13,$D$3:$D$8)+U13)) -> 2.976 | W13: =S12 -> 33.333333 | AH13: 11 | AI13: {=INDEX('PROYEC. SEMACU'!$J$2:$J$13,11)} -> 20.22 | AJ13: =IFERROR((INDEX($W$3:$W$14,MATCH(AI13,$R$3:$R$14))-(AI13+(AI13*0.075)*INDEX($U$3:$U$14,MATCH(AI13,$R$3:$R$14))))*INDEX($U$3:$U$14,MATCH(AI13,$R$3:$R$14)),"") -> -1.2965 | AK13: =IF(AJ13<0,ABS(AJ13)/(AI13*0.15),0) -> 0.42746456 | AL13: =IFERROR(AK13*INDEX($V$3:$V$14,MATCH(AI13,$R$3:$R$14))+(1-AK13)*INDEX($T$3:$T$14,MATCH(AI13,$R$3:$R$14)),"") -> 2.4712458 | AM13: =IFERROR((INDEX($P$3:$P$20,MATCH(AI13,$K$3:$K$20))-(AI13+(AI13*0.075)*INDEX($N$3:$N$20,MATCH(AI13,$K$3:$K$20))))*INDEX($N$3:$N31,MATCH(AI13,$K$3:$K$20)),"") -> -0.67336726 | AN13: =IF(AM13<0,ABS(AM13)/(AI13*0.15),0) -> 0.22201361 | AO13: =IFERROR(AN13*INDEX($O$3:$O$20,MATCH(AI13,$K$3:$K$20))+(1-AN13)*INDEX($M$3:$M$20,MATCH(AI13,$K$3:$K$20)),"") -> 2.7269
A14: 70.5 | B14: 91 | C14: =(454/A14)/0.66 -> 9.7571459 | D14: =(454/B14)/0.66 -> 7.5591076 | E14: =C14-D14 -> 2.1980384 | F14: 1.3 | G14: =IF(I14,F14*2.2*I12-0.132,F14*2.2*I12) -> 1.9162 | H14: =G14/2.2 -> 0.871 | I14: FALSE | K14: =K13+$E$19/2 -> 20.965135 | L14: =K14+$E$19/2 -> 22.553403 | M14: =INDEX($G$14:$G$22,MATCH(K14,$D$14:$D$22)) -> 2.7269 | N14: 1 | O14: =INDEX($G$14:$G$22,(MATCH(K14,$D$14:$D$22)+N14)) -> 2.948 | P14: =L14 -> 22.553403 | R14: =R13+$E$8/2 -> 41.666667 | S14: =R14+$E$8/2 -> 50 | T14: =INDEX($G$3:$G$8,MATCH(R14,$D$3:$D$8)) -> 3.255 | U14: 0 | V14: =INDEX($G$3:$G$8,(MATCH(R14,$D$3:$D$8)+U14)) -> 3.255 | W14: =S14 -> 50 | AH14: RES | AI14: {=INDEX('PROYEC. SEMACU'!$J$2:$J$13,12)} -> 30.96 | AJ14: =IFERROR((INDEX($W$3:$W$14,MATCH(AI14,$R$3:$R$14))-(AI14+(AI14*0.075)*INDEX($U$3:$U$14,MATCH(AI14,$R$3:$R$14))))*INDEX($U$3:$U$14,MATCH(AI14,$R$3:$R$14)),"") -> 0.051333333 | AK14: =IF(AJ14<0,ABS(AJ14)/(AI14*0.15),0) -> 0 | AL14: =IFERROR(AK14*INDEX($V$3:$V$14,MATCH(AI14,$R$3:$R$14))+(1-AK14)*INDEX($T$3:$T$14,MATCH(AI14,$R$3:$R$14)),"") -> 2.976 | AM14: =IFERROR((INDEX($P$3:$P$20,MATCH(AI14,$K$3:$K$20))-(AI14+(AI14*0.075)*INDEX($N$3:$N$20,MATCH(AI14,$K$3:$K$20))))*INDEX($N$3:$N32,MATCH(AI14,$K$3:$K$20)),"") -> 0.27306282 | AN14: =IF(AM14<0,ABS(AM14)/(AI14*0.15),0) -> 0 | AO14: =IFERROR(AN14*INDEX($O$3:$O$20,MATCH(AI14,$K$3:$K$20))+(1-AN14)*INDEX($M$3:$M$20,MATCH(AI14,$K$3:$K$20)),"") -> 3.2428
A15: 60.5 | B15: 70.5 | C15: =(454/A15)/0.66 -> 11.369897 | D15: =(454/B15)/0.66 -> 9.7571459 | E15: =C15-D15 -> 1.6127514 | F15: 1.5 | G15: =IF(I15,F15*2.2*I12-0.132,F15*2.2*I12) -> 2.211 | H15: =G15/2.2 -> 1.005 | I15: FALSE | K15: =D20 -> 22.553403 | L15: =K15+$E$20/2 -> 24.764521 | M15: =INDEX($G$14:$G$22,MATCH(K15,$D$14:$D$22)) -> 2.948 | N15: -1 | O15: =INDEX($G$14:$G$22,(MATCH(K15,$D$14:$D$22)+N15)) -> 2.7269 | P15: =L14 -> 22.553403
A16: 50.5 | B16: 60.5 | C16: =(454/A16)/0.66 -> 13.621362 | D16: =(454/B16)/0.66 -> 11.369897 | E16: =C16-D16 -> 2.2514648 | F16: 1.65 | G16: =IF(I16,F16*2.2*I12-0.132,F16*2.2*I12) -> 2.4321 | H16: =G16/2.2 -> 1.1055 | I16: FALSE | K16: =K15+$E$20/2 -> 24.764521 | L16: =K16+$E$20/2 -> 26.975639 | M16: =INDEX($G$14:$G$22,MATCH(K16,$D$14:$D$22)) -> 2.948 | N16: 1 | O16: =INDEX($G$14:$G$22,(MATCH(K16,$D$14:$D$22)+N16)) -> 3.2428 | P16: =L16 -> 26.975639
A17: 40.5 | B17: 50.5 | C17: =(454/A17)/0.66 -> 16.984661 | D17: =(454/B17)/0.66 -> 13.621362 | E17: =C17-D17 -> 3.3632993 | F17: 1.8 | G17: =IF(I17,F17*2.2*I12-0.132,F17*2.2*I12) -> 2.6532 | H17: =G17/2.2 -> 1.206 | I17: FALSE | K17: =D21 -> 26.975639 | L17: =K17+$E$21/2 -> 30.265351 | M17: =INDEX($G$14:$G$22,MATCH(K17,$D$14:$D$22)) -> 3.2428 | N17: -1 | O17: =INDEX($G$14:$G$22,(MATCH(K17,$D$14:$D$22)+N17)) -> 2.948 | P17: =L16 -> 26.975639
A18: 35.5 | B18: 40.5 | C18: =(454/A18)/0.66 -> 19.376867 | D18: =(454/B18)/0.66 -> 16.984661 | E18: =C18-D18 -> 2.3922058 | F18: 1.85 | G18: =IF(I18,F18*2.2*0.66-0.132,F18*2.2*I12) -> 2.7269 | H18: =G18/2.2 -> 1.2395 | I18: FALSE | K18: =K17+$E$21/2 -> 30.265351 | L18: =K18+$E$21/2 -> 33.555063 | M18: =INDEX($G$14:$G$22,MATCH(K18,$D$14:$D$22)) -> 3.2428 | N18: 1 | O18: =INDEX($G$14:$G$22,(MATCH(K18,$D$14:$D$22)+N18)) -> 3.5376 | P18: =L18 -> 33.555063
A19: 30.5 | B19: 35.5 | C19: =(454/A19)/0.66 -> 22.553403 | D19: =(454/B19)/0.66 -> 19.376867 | E19: =C19-D19 -> 3.1765356 | F19: 1.85 | G19: =IF(I19,F19*2.2*0.66-0.132,F19*2.2*I12) -> 2.7269 | H19: =G19/2.2 -> 1.2395 | I19: FALSE | K19: =D22 -> 33.555063 | L19: =K19+$E$22/2 -> 38.273744 | M19: =INDEX($G$14:$G$22,MATCH(K19,$D$14:$D$22)) -> 3.5376 | N19: -1 | O19: =INDEX($G$14:$G$22,(MATCH(K19,$D$14:$D$22)+N19)) -> 3.2428 | P19: =L18 -> 33.555063
A20: 25.5 | B20: 30.5 | C20: =(454/A20)/0.66 -> 26.975639 | D20: =(454/B20)/0.66 -> 22.553403 | E20: =C20-D20 -> 4.4222359 | F20: 2 | G20: =IF(I20,F20*2.2*0.66-0.132,F20*2.2*I12) -> 2.948 | H20: =G20/2.2 -> 1.34 | I20: FALSE | K20: =K19+$E$22/2 -> 38.273744 | L20: =K20+$E$22/2 -> 42.992424 | M20: =INDEX($G$14:$G$22,MATCH(K20,$D$14:$D$22)) -> 3.5376 | N20: 0 | O20: =INDEX($G$14:$G$22,(MATCH(K20,$D$14:$D$22)+N20)) -> 3.5376 | P20: =L20 -> 42.992424
A21: 20.5 | B21: 25.5 | C21: =(454/A21)/0.66 -> 33.555063 | D21: =(454/B21)/0.66 -> 26.975639 | E21: =C21-D21 -> 6.5794241 | F21: 2.2 | G21: =IF(I21,F21*2.2*0.66-0.132,F21*2.2*I12) -> 3.2428 | H21: =G21/2.2 -> 1.474 | I21: FALSE
A22: 16 | B22: 20.5 | C22: =(454/A22)/0.66 -> 42.992424 | D22: =(454/B22)/0.66 -> 33.555063 | E22: =C22-D22 -> 9.4373614 | F22: 2.4 | G22: =IF(I22,F22*2.2*0.66-0.132,F22*2.2*I12) -> 3.5376 | H22: =G22/2.2 -> 1.608 | I22: FALSE

Sheet Masterline
A1: PESO MIN (g) | B1: PESO MAX (g) | C1: %BW Min | D1: %BW Max | E1: % BW diff
A2: 0.1 | B2: 0.24 | C2: ='Masterline-original'!C2*1.2 -> 27 | D2: ='Masterline-original'!D2*1.2 -> 38.988 | E2: =D2-C2 -> 11.988
A3: 0.25 | B3: 0.49 | C3: ='Masterline-original'!C3*1.2 -> 18.444 | D3: ='Masterline-original'!D3*1.2 -> 23.748 | E3: =D3-C3 -> 5.304
A4: 0.5 | B4: 0.99 | C4: ='Masterline-original'!C4*1.2 -> 14.124 | D4: ='Masterline-original'!D4*1.2 -> 16.632 | E4: =D4-C4 -> 2.508
A5: 1 | B5: 1.99 | C5: ='Masterline-original'!C5*1.2 -> 12.24 | D5: ='Masterline-original'!D5*1.2 -> 14.112 | E5: =D5-C5 -> 1.872
A6: 2 | B6: 2.99 | C6: ='Masterline-original'!C6*1.2 -> 9.636 | D6: ='Masterline-original'!D6*1.2 -> 11.076 | E6: =D6-C6 -> 1.44
A7: 3 | B7: 3.99 | C7: ='Masterline-original'!C7*1.2 -> 8.532 | D7: ='Masterline-original'!D7*1.2 -> 9.624 | E7: =D7-C7 -> 1.092
A8: 4 | B8: 4.99 | C8: ='Masterline-original'!C8*1.2 -> 7.488 | D8: ='Masterline-original'!D8*1.2 -> 8.52 | E8: =D8-C8 -> 1.032
A9: 5 | B9: 5.99 | C9: ='Masterline-original'!C9*1.2 -> 6.9 | D9: ='Masterline-original'!D9*1.2 -> 7.476 | E9: =D9-C9 -> 0.576
A10: 6 | B10: 6.99 | C10: ='Masterline-original'!C10*1.2 -> 6.3 | D10: ='Masterline-original'!D10*1.2 -> 6.888 | E10: =D10-C10 -> 0.588
A11: 7 | B11: 7.99 | C11: ='Masterline-original'!C11*1.2 -> 5.724 | D11: ='Masterline-original'!D11*1.2 -> 6.348 | E11: =D11-C11 -> 0.624
A12: 8 | B12: 8.99 | C12: ='Masterline-original'!C12*1.2 -> 5.316 | D12: ='Masterline-original'!D12*1.2 -> 5.604 | E12: =D12-C12 -> 0.288
A13: 9 | B13: 9.99 | C13: ='Masterline-original'!C13*1.2 -> 5.016 | D13: ='Masterline-original'!D13*1.2 -> 5.304 | E13: =D13-C13 -> 0.288
... A34: 30 | B34: 30.99 | C34: ='Masterline-original'!C34*1.2 -> 2.568 | D34: ='Masterline-original'!D34*1.2 -> 2.628 | E34: =D34-C34 -> 0.06

Sheet Masterline-original
A1: PESO MIN (g) | B1: PESO MAX (g) | C1: %BW Min | D1: %BW Max | E1: % BW diff
A2: 0.1 | B2: 0.24 | C2: 22.5 | D2: 32.49 | E2: =D2-C2 -> 9.99
A3: 0.25 | B3: 0.49 | C3: 15.37 | D3: 19.79 | E3: =D3-C3 -> 4.42
A4: 0.5 | B4: 0.99 | C4: 11.77 | D4: 13.86 | E4: =D4-C4 -> 2.09
A5: 1 | B5: 1.99 | C5: 10.2 | D5: 11.76 | E5: =D5-C5 -> 1.56
A6: 2 | B6: 2.99 | C6: 8.03 | D6: 9.23 | E6: =D6-C6 -> 1.2
A7: 3 | B7: 3.99 | C7: 7.11 | D7: 8.02 | E7: =D7-C7 -> 0.91
A8: 4 | B8: 4.99 | C8: 6.24 | D8: 7.1 | E8: =D8-C8 -> 0.86
A9: 5 | B9: 5.99 | C9: 5.75 | D9: 6.23 | E9: =D9-C9 -> 0.48
A10: 6 | B10: 6.99 | C10: 5.25 | D10: 5.74 | E10: =D10-C10 -> 0.49
A11: 7 | B11: 7.99 | C11: 4.77 | D11: 5.29 | E11: =D11-C11 -> 0.52
A12: 8 | B12: 8.99 | C12: 4.43 | D12: 4.67 | E12: =D12-C12 -> 0.24
A13: 9 | B13: 9.99 | C13: 4.18 | D13: 4.42 | E13: =D13-C13 -> 0.24
... A34: 30 | B34: 30.99 | C34: 2.14 | D34: 2.19 | E34: =D34-C34 -> 0.05

Sheet Sheet22
A1: PESO (g) | B1: %BW
A2: 0.1 | B2: 32.49
A3: 0.24 | B3: 22.5
A4: 0.25 | B4: 19.79
A5: 0.49 | B5: 15.37
A6: 0.5 | B6: 13.86
A7: 0.99 | B7: 11.77
A8: 1 | B8: 11.76
A9: 1.99 | B9: 10.2
A10: 2 | B10: 9.23
A11: 2.99 | B11: 8.03
A12: 3 | B12: 8.02
A13: 3.99 | B13: 7.11
... A67: 30.99 | B67: 2.14

Sheet SKRETTING PRECRIA
A1: / | B1: PL/GR MAX | C1: Min PESO (g) | D1: Max PESO (g) | E1: MAX-MIN PESO | F1: % BW/DIA MIN | G1: % BW/DIA MAX | H1: % BW diff
A2: 300 | B2: 150 | C2: =1/A2 -> 0.0033333333 | D2: =1/B2 -> 0.0066666667 | E2: =D2-C2 -> 0.0033333333 | F2: 180 | G2: 200 | H2: =G2-F2 -> 20
A3: 150 | B3: 110 | C3: =1/A3 -> 0.0066666667 | D3: =1/B3 -> 0.0090909091 | E3: =D3-C3 -> 0.0024242424 | F3: 160 | G3: 180 | H3: =G3-F3 -> 20
A4: 110 | B4: 100 | C4: =1/A4 -> 0.0090909091 | D4: =1/B4 -> 0.01 | E4: =D4-C4 -> 0.00090909091 | F4: 145 | G4: 160 | H4: =G4-F4 -> 15
A5: 100 | B5: 80 | C5: =1/A5 -> 0.01 | D5: =1/B5 -> 0.0125 | E5: =D5-C5 -> 0.0025 | F5: 140 | G5: 145 | H5: =G5-F5 -> 5
A6: 80 | B6: 70 | C6: =1/A6 -> 0.0125 | D6: =1/B6 -> 0.014285714 | E6: =D6-C6 -> 0.0017857143 | F6: 135 | G6: 140 | H6: =G6-F6 -> 5
A7: 70 | B7: 60 | C7: =1/A7 -> 0.014285714 | D7: =1/B7 -> 0.016666667 | E7: =D7-C7 -> 0.0023809524 | F7: 130 | G7: 135 | H7: =G7-F7 -> 5
A8: 60 | B8: 50 | C8: =1/A8 -> 0.016666667 | D8: =1/B8 -> 0.02 | E8: =D8-C8 -> 0.0033333333 | F8: 120 | G8: 130 | H8: =G8-F8 -> 10
A9: 50 | B9: 40 | C9: =1/A9 -> 0.02 | D9: =1/B9 -> 0.025 | E9: =D9-C9 -> 0.005 | F9: 115 | G9: 120 | H9: =G9-F9 -> 5
A10: 40 | B10: 30 | C10: =1/A10 -> 0.025 | D10: =1/B10 -> 0.033333333 | E10: =D10-C10 -> 0.0083333333 | F10: 105 | G10: 115 | H10: =G10-F10 -> 10
A11: 30 | B11: 25 | C11: =1/A11 -> 0.033333333 | D11: =1/B11 -> 0.04 | E11: =D11-C11 -> 0.0066666667 | F11: 95 | G11: 105 | H11: =G11-F11 -> 10
A12: 25 | B12: 20 | C12: =1/A12 -> 0.04 | D12: =1/B12 -> 0.05 | E12: =D12-C12 -> 0.01 | F12: 90 | G12: 95 | H12: =G12-F12 -> 5
A13: 20 | B13: 18 | C13: =1/A13 -> 0.05 | D13: =1/B13 -> 0.055555556 | E13: =D13-C13 -> 0.0055555556 | F13: 80 | G13: 90 | H13: =G13-F13 -> 10
... A25: 1.2 | B25: 1 | C25: =1/A25 -> 0.83333333 | D25: =1/B25 -> 1 | E25: =D25-C25 -> 0.16666667 | F25: 15 | G25: 16 | H25: =G25-F25 -> 1

Sheet PROYECCION PRECRIA
A1: S | B1: CANTIDAD | D1: CREC. PROME. | E1: SOBREV. % | F1: DIAS | G1: TOT BALANC | H1: KILOS LARVA | I1: FC
A2: =1/180 -> 0.0055555556 | B2: 2800000 | D2: 0.29 | E2: 0.7 | F2: 20 | G2: {=sum(E4:INDIRECT("E"&(F2+3)))} -> 2138.3055 | H2: {=B2*INDIRECT("B"&(3+F2))/1000} -> 1930.3679 | I2: =G2/H2 -> 1.1077192
A3: DIAS | B3: PESO (g) | C3: CREC | D3: % PESO DIA | E3: DIARIO (Kg) | F3: SACOS | G3: 6 DOSIS (Kg) 5 del dia | H3: 6 DOSIS (Kg) Ultima dosis | I3: 4 DOSIS (Kg)
A4: 1 | B4: =A2 -> 0.0055555556 | C4: =C5+0.01 -> 0.38 | D4: {=IFERROR((LOOKUP(B4,'SKRETTING PRECRIA'!$C$2:$C$25,'SKRETTING PRECRIA'!$G$2:$G$34)-((B4-INDEX('SKRETTING PRECRIA'!$C$2:$C$25,MATCH(B4,'SKRETTING PRECRIA'!$C$2:$C$25),1))/INDEX('SKRETTING PRECRIA'!$E$2:$E$25,MATCH(B4,'SKRETTING PRECRIA'!$C$2:$C$25),1))*INDEX('SKRETTING PRECRIA'!$H$2:$H$25,MATCH(B4,'SKRETTING PRECRIA'!$C$2:$C$25),1))/100,"")} -> 1.8666667 | E4: =(B4/1000)*$B$2*$E$2*D4 -> 20.325926 | F4: =E4/25 -> 0.81303704 | G4: =E4/8 -> 2.5407407 | H4: =E4*3/8 -> 7.6222222 | I4: =E4/4 -> 5.0814815
A5: 2 | B5: =B4*(1+C4) -> 0.0076666667 | C5: =C6+0.01 -> 0.37 | D5: {=IFERROR((LOOKUP(B5,'SKRETTING PRECRIA'!$C$2:$C$25,'SKRETTING PRECRIA'!$G$2:$G$34)-((B5-INDEX('SKRETTING PRECRIA'!$C$2:$C$25,MATCH(B5,'SKRETTING PRECRIA'!$C$2:$C$25),1))/INDEX('SKRETTING PRECRIA'!$E$2:$E$25,MATCH(B5,'SKRETTING PRECRIA'!$C$2:$C$25),1))*INDEX('SKRETTING PRECRIA'!$H$2:$H$25,MATCH(B5,'SKRETTING PRECRIA'!$C$2:$C$25),1))/100,"")} -> 1.7175 | E5: =(B5/1000)*$B$2*$E$2*D5 -> 25.8083 | F5: =E5/25 -> 1.032332 | G5: =E5*0.6/4 -> 3.871245 | H5: =E5*0.4 -> 10.32332 | I5: =E5/4 -> 6.452075
A6: 3 | B6: =B5*(1+C5) -> 0.010503333 | C6: =C7+0.01 -> 0.36 | D6: {=IFERROR((LOOKUP(B6,'SKRETTING PRECRIA'!$C$2:$C$25,'SKRETTING PRECRIA'!$G$2:$G$34)-((B6-INDEX('SKRETTING PRECRIA'!$C$2:$C$25,MATCH(B6,'SKRETTING PRECRIA'!$C$2:$C$25),1))/INDEX('SKRETTING PRECRIA'!$E$2:$E$25,MATCH(B6,'SKRETTING PRECRIA'!$C$2:$C$25),1))*INDEX('SKRETTING PRECRIA'!$H$2:$H$25,MATCH(B6,'SKRETTING PRECRIA'!$C$2:$C$25),1))/100,"")} -> 1.4399333 | E6: =(B6/1000)*$B$2*$E$2*D6 -> 29.643236 | F6: =E6/25 -> 1.1857294 | G6: =E6*0.6/4 -> 4.4464853 | H6: =E6*0.4 -> 11.857294 | I6: =E6/4 -> 7.4108089
A7: 4 | B7: =B6*(1+C6) -> 0.014284533 | C7: =C8+0.01 -> 0.35 | D7: {=IFERROR((LOOKUP(B7,'SKRETTING PRECRIA'!$C$2:$C$25,'SKRETTING PRECRIA'!$G$2:$G$34)-((B7-INDEX('SKRETTING PRECRIA'!$C$2:$C$25,MATCH(B7,'SKRETTING PRECRIA'!$C$2:$C$25),1))/INDEX('SKRETTING PRECRIA'!$E$2:$E$25,MATCH(B7,'SKRETTING PRECRIA'!$C$2:$C$25),1))*INDEX('SKRETTING PRECRIA'!$H$2:$H$25,MATCH(B7,'SKRETTING PRECRIA'!$C$2:$C$25),1))/100,"")} -> 1.3500331 | E7: =(B7/1000)*$B$2*$E$2*D7 -> 37.797801 | F7: =E7/25 -> 1.511912 | G7: =E7*0.6/4 -> 5.6696701 | H7: =E7*0.4 -> 15.11912 | I7: =E7/4 -> 9.4494502
A8: 5 | B8: =B7*(1+C7) -> 0.01928412 | C8: =C9+0.01 -> 0.34 | D8: {=IFERROR((LOOKUP(B8,'SKRETTING PRECRIA'!$C$2:$C$25,'SKRETTING PRECRIA'!$G$2:$G$34)-((B8-INDEX('SKRETTING PRECRIA'!$C$2:$C$25,MATCH(B8,'SKRETTING PRECRIA'!$C$2:$C$25),1))/INDEX('SKRETTING PRECRIA'!$E$2:$E$25,MATCH(B8,'SKRETTING PRECRIA'!$C$2:$C$25),1))*INDEX('SKRETTING PRECRIA'!$H$2:$H$25,MATCH(B8,'SKRETTING PRECRIA'!$C$2:$C$25),1))/100,"")} -> 1.2214764 | E8: =(B8/1000)*$B$2*$E$2*D8 -> 46.167991 | F8: =E8/25 -> 1.8467196 | G8: =E8*0.6/4 -> 6.9251987 | H8: =E8*0.4 -> 18.467196 | I8: =E8/4 -> 11.541998
A9: 6 | B9: =B8*(1+C8) -> 0.025840721 | C9: =C10+0.01 -> 0.33 | D9: {=IFERROR((LOOKUP(B9,'SKRETTING PRECRIA'!$C$2:$C$25,'SKRETTING PRECRIA'!$G$2:$G$34)-((B9-INDEX('SKRETTING PRECRIA'!$C$2:$C$25,MATCH(B9,'SKRETTING PRECRIA'!$C$2:$C$25),1))/INDEX('SKRETTING PRECRIA'!$E$2:$E$25,MATCH(B9,'SKRETTING PRECRIA'!$C$2:$C$25),1))*INDEX('SKRETTING PRECRIA'!$H$2:$H$25,MATCH(B9,'SKRETTING PRECRIA'!$C$2:$C$25),1))/100,"")} -> 1.1399113 | E9: =(B9/1000)*$B$2*$E$2*D9 -> 57.734017 | F9: =E9/25 -> 2.3093607 | G9: =E9*0.6/4 -> 8.6601025 | H9: =E9*0.4 -> 23.093607 | I9: =E9/4 -> 14.433504
A10: 7 | B10: =B9*(1+C9) -> 0.034368159 | C10: =C11+0.01 -> 0.32 | D10: {=IFERROR((LOOKUP(B10,'SKRETTING PRECRIA'!$C$2:$C$25,'SKRETTING PRECRIA'!$G$2:$G$34)-((B10-INDEX('SKRETTING PRECRIA'!$C$2:$C$25,MATCH(B10,'SKRETTING PRECRIA'!$C$2:$C$25),1))/INDEX('SKRETTING PRECRIA'!$E$2:$E$25,MATCH(B10,'SKRETTING PRECRIA'!$C$2:$C$25),1))*INDEX('SKRETTING PRECRIA'!$H$2:$H$25,MATCH(B10,'SKRETTING PRECRIA'!$C$2:$C$25),1))/100,"")} -> 1.0344776 | E10: =(B10/1000)*$B$2*$E$2*D10 -> 69.684058 | F10: =E10/25 -> 2.7873623 | G10: =E10*0.6/4 -> 10.452609 | H10: =E10*0.4 -> 27.873623 | I10: =E10/4 -> 17.421015
A11: 8 | B11: =B10*(1+C10) -> 0.045365969 | C11: =C12+0.01 -> 0.31 | D11: {=IFERROR((LOOKUP(B11,'SKRETTING PRECRIA'!$C$2:$C$25,'SKRETTING PRECRIA'!$G$2:$G$34)-((B11-INDEX('SKRETTING PRECRIA'!$C$2:$C$25,MATCH(B11,'SKRETTING PRECRIA'!$C$2:$C$25),1))/INDEX('SKRETTING PRECRIA'!$E$2:$E$25,MATCH(B11,'SKRETTING PRECRIA'!$C$2:$C$25),1))*INDEX('SKRETTING PRECRIA'!$H$2:$H$25,MATCH(B11,'SKRETTING PRECRIA'!$C$2:$C$25),1))/100,"")} -> 0.92317015 | E11: =(B11/1000)*$B$2*$E$2*D11 -> 82.085798 | F11: =E11/25 -> 3.2834319 | G11: =E11*0.6/4 -> 12.31287 | H11: =E11*0.4 -> 32.834319 | I11: =E11/4 -> 20.521449
A12: 9 | B12: =B11*(1+C11) -> 0.05942942 | C12: =C13+0.01 -> 0.3 | D12: {=IFERROR((LOOKUP(B12,'SKRETTING PRECRIA'!$C$2:$C$25,'SKRETTING PRECRIA'!$G$2:$G$34)-((B12-INDEX('SKRETTING PRECRIA'!$C$2:$C$25,MATCH(B12,'SKRETTING PRECRIA'!$C$2:$C$25),1))/INDEX('SKRETTING PRECRIA'!$E$2:$E$25,MATCH(B12,'SKRETTING PRECRIA'!$C$2:$C$25),1))*INDEX('SKRETTING PRECRIA'!$H$2:$H$25,MATCH(B12,'SKRETTING PRECRIA'!$C$2:$C$25),1))/100,"")} -> 0.78256761 | E12: =(B12/1000)*$B$2*$E$2*D12 -> 91.154777 | F12: =E12/25 -> 3.6461911 | G12: =E12*0.6/4 -> 13.673217 | H12: =E12*0.4 -> 36.461911 | I12: =E12/4 -> 22.788694
A13: 10 | B13: =B12*(1+C12) -> 0.077258246 | C13: =D2 -> 0.29 | D13: {=IFERROR((LOOKUP(B13,'SKRETTING PRECRIA'!$C$2:$C$25,'SKRETTING PRECRIA'!$G$2:$G$34)-((B13-INDEX('SKRETTING PRECRIA'!$C$2:$C$25,MATCH(B13,'SKRETTING PRECRIA'!$C$2:$C$25),1))/INDEX('SKRETTING PRECRIA'!$E$2:$E$25,MATCH(B13,'SKRETTING PRECRIA'!$C$2:$C$25),1))*INDEX('SKRETTING PRECRIA'!$H$2:$H$25,MATCH(B13,'SKRETTING PRECRIA'!$C$2:$C$25),1))/100,"")} -> 0.69760354 | E13: =(B13/1000)*$B$2*$E$2*D13 -> 105.63543 | F13: =E13/25 -> 4.2254171 | G13: =E13*0.6/4 -> 15.845314 | H13: =E13*0.4 -> 42.254171 | I13: =E13/4 -> 26.408857
A14: 11 | B14: =B13*(1+C13) -> 0.099663137 | C14: =C13-0.01 -> 0.28 | D14: {=IFERROR((LOOKUP(B14,'SKRETTING PRECRIA'!$C$2:$C$25,'SKRETTING PRECRIA'!$G$2:$G$34)-((B14-INDEX('SKRETTING PRECRIA'!$C$2:$C$25,MATCH(B14,'SKRETTING PRECRIA'!$C$2:$C$25),1))/INDEX('SKRETTING PRECRIA'!$E$2:$E$25,MATCH(B14,'SKRETTING PRECRIA'!$C$2:$C$25),1))*INDEX('SKRETTING PRECRIA'!$H$2:$H$25,MATCH(B14,'SKRETTING PRECRIA'!$C$2:$C$25),1))/100,"")} -> 0.55666747 | E14: =(B14/1000)*$B$2*$E$2*D14 -> 108.73928 | F14: =E14/25 -> 4.3495714 | G14: =E14*0.6/4 -> 16.310893 | H14: =E14*0.4 -> 43.495714 | I14: =E14/4 -> 27.184821
A15: 12 | B15: =B14*(1+C14) -> 0.12756882 | C15: =C14-0.01 -> 0.27 | D15: {=IFERROR((LOOKUP(B15,'SKRETTING PRECRIA'!$C$2:$C$25,'SKRETTING PRECRIA'!$G$2:$G$34)-((B15-INDEX('SKRETTING PRECRIA'!$C$2:$C$25,MATCH(B15,'SKRETTING PRECRIA'!$C$2:$C$25),1))/INDEX('SKRETTING PRECRIA'!$E$2:$E$25,MATCH(B15,'SKRETTING PRECRIA'!$C$2:$C$25),1))*INDEX('SKRETTING PRECRIA'!$H$2:$H$25,MATCH(B15,'SKRETTING PRECRIA'!$C$2:$C$25),1))/100,"")} -> 0.44815823 | E15: =(B15/1000)*$B$2*$E$2*D15 -> 112.05519 | F15: =E15/25 -> 4.4822076 | G15: =E15*0.6/4 -> 16.808278 | H15: =E15*0.4 -> 44.822076 | I15: =E15/4 -> 28.013797
A16: 13 | B16: =B15*(1+C15) -> 0.1620124 | C16: =C15-0.01 -> 0.26 | D16: {=IFERROR((LOOKUP(B16,'SKRETTING PRECRIA'!$C$2:$C$25,'SKRETTING PRECRIA'!$G$2:$G$34)-((B16-INDEX('SKRETTING PRECRIA'!$C$2:$C$25,MATCH(B16,'SKRETTING PRECRIA'!$C$2:$C$25),1))/INDEX('SKRETTING PRECRIA'!$E$2:$E$25,MATCH(B16,'SKRETTING PRECRIA'!$C$2:$C$25),1))*INDEX('SKRETTING PRECRIA'!$H$2:$H$25,MATCH(B16,'SKRETTING PRECRIA'!$C$2:$C$25),1))/100,"")} -> 0.36647831 | E16: =(B16/1000)*$B$2*$E$2*D16 -> 116.3731 | F16: =E16/25 -> 4.6549238 | G16: =E16*0.6/4 -> 17.455964 | H16: =E16*0.4 -> 46.549238 | I16: =E16/4 -> 29.093274
A17: 14 | B17: =B16*(1+C16) -> 0.20413562 | C17: =C16-0.01 -> 0.25 | D17: {=IFERROR((LOOKUP(B17,'SKRETTING PRECRIA'!$C$2:$C$25,'SKRETTING PRECRIA'!$G$2:$G$34)-((B17-INDEX('SKRETTING PRECRIA'!$C$2:$C$25,MATCH(B17,'SKRETTING PRECRIA'!$C$2:$C$25),1))/INDEX('SKRETTING PRECRIA'!$E$2:$E$25,MATCH(B17,'SKRETTING PRECRIA'!$C$2:$C$25),1))*INDEX('SKRETTING PRECRIA'!$H$2:$H$25,MATCH(B17,'SKRETTING PRECRIA'!$C$2:$C$25),1))/100,"")} -> 0.29844914 | E17: =(B17/1000)*$B$2*$E$2*D17 -> 119.41124 | F17: =E17/25 -> 4.7764495 | G17: =E17*0.6/4 -> 17.911686 | H17: =E17*0.4 -> 47.764495 | I17: =E17/4 -> 29.852809
A18: 15 | B18: =B17*(1+C17) -> 0.25516952 | C18: =C17-0.01 -> 0.24 | D18: {=IFERROR((LOOKUP(B18,'SKRETTING PRECRIA'!$C$2:$C$25,'SKRETTING PRECRIA'!$G$2:$G$34)-((B18-INDEX('SKRETTING PRECRIA'!$C$2:$C$25,MATCH(B18,'SKRETTING PRECRIA'!$C$2:$C$25),1))/INDEX('SKRETTING PRECRIA'!$E$2:$E$25,MATCH(B18,'SKRETTING PRECRIA'!$C$2:$C$25),1))*INDEX('SKRETTING PRECRIA'!$H$2:$H$25,MATCH(B18,'SKRETTING PRECRIA'!$C$2:$C$25),1))/100,"")} -> 0.27931143 | E18: =(B18/1000)*$B$2*$E$2*D18 -> 139.69266 | F18: =E18/25 -> 5.5877063 | G18: =E18*0.6/4 -> 20.953899 | H18: =E18*0.4 -> 55.877063 | I18: =E18/4 -> 34.923164
A19: 16 | B19: =B18*(1+C18) -> 0.31641021 | C19: =C18-0.01 -> 0.23 | D19: {=IFERROR((LOOKUP(B19,'SKRETTING PRECRIA'!$C$2:$C$25,'SKRETTING PRECRIA'!$G$2:$G$34)-((B19-INDEX('SKRETTING PRECRIA'!$C$2:$C$25,MATCH(B19,'SKRETTING PRECRIA'!$C$2:$C$25),1))/INDEX('SKRETTING PRECRIA'!$E$2:$E$25,MATCH(B19,'SKRETTING PRECRIA'!$C$2:$C$25),1))*INDEX('SKRETTING PRECRIA'!$H$2:$H$25,MATCH(B19,'SKRETTING PRECRIA'!$C$2:$C$25),1))/100,"")} -> 0.25634617 | E19: =(B19/1000)*$B$2*$E$2*D19 -> 158.97667 | F19: =E19/25 -> 6.3590668 | G19: =E19*0.6/4 -> 23.8465 | H19: =E19*0.4 -> 63.590668 | I19: =E19/4 -> 39.744167
A20: 17 | B20: =B19*(1+C19) -> 0.38918456 | C20: =C19-0.01 -> 0.22 | D20: {=IFERROR((LOOKUP(B20,'SKRETTING PRECRIA'!$C$2:$C$25,'SKRETTING PRECRIA'!$G$2:$G$34)-((B20-INDEX('SKRETTING PRECRIA'!$C$2:$C$25,MATCH(B20,'SKRETTING PRECRIA'!$C$2:$C$25),1))/INDEX('SKRETTING PRECRIA'!$E$2:$E$25,MATCH(B20,'SKRETTING PRECRIA'!$C$2:$C$25),1))*INDEX('SKRETTING PRECRIA'!$H$2:$H$25,MATCH(B20,'SKRETTING PRECRIA'!$C$2:$C$25),1))/100,"")} -> 0.22486695 | E20: =(B20/1000)*$B$2*$E$2*D20 -> 171.5289 | F20: =E20/25 -> 6.8611559 | G20: =E20*0.6/4 -> 25.729335 | H20: =E20*0.4 -> 68.611559 | I20: =E20/4 -> 42.882225
A21: 18 | B21: =B20*(1+C20) -> 0.47480516 | C21: =C20-0.01 -> 0.21 | D21: {=IFERROR((LOOKUP(B21,'SKRETTING PRECRIA'!$C$2:$C$25,'SKRETTING PRECRIA'!$G$2:$G$34)-((B21-INDEX('SKRETTING PRECRIA'!$C$2:$C$25,MATCH(B21,'SKRETTING PRECRIA'!$C$2:$C$25),1))/INDEX('SKRETTING PRECRIA'!$E$2:$E$25,MATCH(B21,'SKRETTING PRECRIA'!$C$2:$C$25),1))*INDEX('SKRETTING PRECRIA'!$H$2:$H$25,MATCH(B21,'SKRETTING PRECRIA'!$C$2:$C$25),1))/100,"")} -> 0.20503897 | E21: =(B21/1000)*$B$2*$E$2*D21 -> 190.81298 | F21: =E21/25 -> 7.6325191 | G21: =E21*0.6/4 -> 28.621947 | H21: =E21*0.4 -> 76.325191 | I21: =E21/4 -> 47.703244
A22: 19 | B22: =B21*(1+C21) -> 0.57451424 | C22: =C21-0.01 -> 0.2 | D22: {=IFERROR((LOOKUP(B22,'SKRETTING PRECRIA'!$C$2:$C$25,'SKRETTING PRECRIA'!$G$2:$G$34)-((B22-INDEX('SKRETTING PRECRIA'!$C$2:$C$25,MATCH(B22,'SKRETTING PRECRIA'!$C$2:$C$25),1))/INDEX('SKRETTING PRECRIA'!$E$2:$E$25,MATCH(B22,'SKRETTING PRECRIA'!$C$2:$C$25),1))*INDEX('SKRETTING PRECRIA'!$H$2:$H$25,MATCH(B22,'SKRETTING PRECRIA'!$C$2:$C$25),1))/100,"")} -> 0.19105829 | E22: =(B22/1000)*$B$2*$E$2*D22 -> 215.14079 | F22: =E22/25 -> 8.6056316 | G22: =E22*0.6/4 -> 32.271119 | H22: =E22*0.4 -> 86.056316 | I22: =E22/4 -> 53.785198
A23: 20 | B23: =B22*(1+C22) -> 0.68941709 | C23: =C22-0.01 -> 0.19 | D23: {=IFERROR((LOOKUP(B23,'SKRETTING PRECRIA'!$C$2:$C$25,'SKRETTING PRECRIA'!$G$2:$G$34)-((B23-INDEX('SKRETTING PRECRIA'!$C$2:$C$25,MATCH(B23,'SKRETTING PRECRIA'!$C$2:$C$25),1))/INDEX('SKRETTING PRECRIA'!$E$2:$E$25,MATCH(B23,'SKRETTING PRECRIA'!$C$2:$C$25),1))*INDEX('SKRETTING PRECRIA'!$H$2:$H$25,MATCH(B23,'SKRETTING PRECRIA'!$C$2:$C$25),1))/100,"")} -> 0.17726995 | E23: =(B23/1000)*$B$2*$E$2*D23 -> 239.53735 | F23: =E23/25 -> 9.5814939 | G23: =E23*0.6/4 -> 35.930602 | H23: =E23*0.4 -> 95.814939 | I23: =E23/4 -> 59.884337
A24: 21 | B24: =B23*(1+C23) -> 0.82040634 | C24: =C23-0.01 -> 0.18 | D24: {=IFERROR((LOOKUP(B24,'SKRETTING PRECRIA'!$C$2:$C$25,'SKRETTING PRECRIA'!$G$2:$G$34)-((B24-INDEX('SKRETTING PRECRIA'!$C$2:$C$25,MATCH(B24,'SKRETTING PRECRIA'!$C$2:$C$25),1))/INDEX('SKRETTING PRECRIA'!$E$2:$E$25,MATCH(B24,'SKRETTING PRECRIA'!$C$2:$C$25),1))*INDEX('SKRETTING PRECRIA'!$H$2:$H$25,MATCH(B24,'SKRETTING PRECRIA'!$C$2:$C$25),1))/100,"")} -> 0.16155124 | E24: =(B24/1000)*$B$2*$E$2*D24 -> 259.77382 | F24: =E24/25 -> 10.390953 | G24: =E24*0.6/4 -> 38.966072 | H24: =E24*0.4 -> 103.90953 | I24: =E24/4 -> 64.943454
A25: 22 | B25: =B24*(1+C24) -> 0.96807948 | C25: =C24-0.01 -> 0.17 | D25: {=IFERROR((LOOKUP(B25,'SKRETTING PRECRIA'!$C$2:$C$25,'SKRETTING PRECRIA'!$G$2:$G$34)-((B25-INDEX('SKRETTING PRECRIA'!$C$2:$C$25,MATCH(B25,'SKRETTING PRECRIA'!$C$2:$C$25),1))/INDEX('SKRETTING PRECRIA'!$E$2:$E$25,MATCH(B25,'SKRETTING PRECRIA'!$C$2:$C$25),1))*INDEX('SKRETTING PRECRIA'!$H$2:$H$25,MATCH(B25,'SKRETTING PRECRIA'!$C$2:$C$25),1))/100,"")} -> 0.15191523 | E25: =(B25/1000)*$B$2*$E$2*D25 -> 288.2494 | F25: =E25/25 -> 11.529976 | G25: =E25*0.6/4 -> 43.237409 | H25: =E25*0.4 -> 115.29976 | I25: =E25/4 -> 72.062349
A26: 23 | B26: =B25*(1+C25) -> 1.132653 | C26: =C25-0.01 -> 0.16 | D26: {=IFERROR((LOOKUP(B26,'SKRETTING PRECRIA'!$C$2:$C$25,'SKRETTING PRECRIA'!$G$2:$G$34)-((B26-INDEX('SKRETTING PRECRIA'!$C$2:$C$25,MATCH(B26,'SKRETTING PRECRIA'!$C$2:$C$25),1))/INDEX('SKRETTING PRECRIA'!$E$2:$E$25,MATCH(B26,'SKRETTING PRECRIA'!$C$2:$C$25),1))*INDEX('SKRETTING PRECRIA'!$H$2:$H$25,MATCH(B26,'SKRETTING PRECRIA'!$C$2:$C$25),1))/100,"")} -> 0.14204082 | E26: =(B26/1000)*$B$2*$E$2*D26 -> 315.3306 | F26: =E26/25 -> 12.613224 | G26: =E26*0.6/4 -> 47.29959 | H26: =E26*0.4 -> 126.13224 | I26: =E26/4 -> 78.832651
A27: 24 | B27: =B26*(1+$D$2) -> 1.4611224 | C27: =C26-0.01 -> 0.15 | D27: {=IFERROR((LOOKUP(B27,'SKRETTING PRECRIA'!$C$2:$C$25,'SKRETTING PRECRIA'!$G$2:$G$34)-((B27-INDEX('SKRETTING PRECRIA'!$C$2:$C$25,MATCH(B27,'SKRETTING PRECRIA'!$C$2:$C$25),1))/INDEX('SKRETTING PRECRIA'!$E$2:$E$25,MATCH(B27,'SKRETTING PRECRIA'!$C$2:$C$25),1))*INDEX('SKRETTING PRECRIA'!$H$2:$H$25,MATCH(B27,'SKRETTING PRECRIA'!$C$2:$C$25),1))/100,"")} -> 0.12233266 | E27: =(B27/1000)*$B$2*$E$2*D27 -> 350.33625 | F27: =E27/25 -> 14.01345 | G27: =E27*0.6/4 -> 52.550437 | H27: =E27*0.4 -> 140.1345 | I27: =E27/4 -> 87.584061
A28: 25 | B28: =B27*(1+$D$2) -> 1.8848478 | C28: =C27-0.01 -> 0.14 | D28: {=IFERROR((LOOKUP(B28,'SKRETTING PRECRIA'!$C$2:$C$25,'SKRETTING PRECRIA'!$G$2:$G$34)-((B28-INDEX('SKRETTING PRECRIA'!$C$2:$C$25,MATCH(B28,'SKRETTING PRECRIA'!$C$2:$C$25),1))/INDEX('SKRETTING PRECRIA'!$E$2:$E$25,MATCH(B28,'SKRETTING PRECRIA'!$C$2:$C$25),1))*INDEX('SKRETTING PRECRIA'!$H$2:$H$25,MATCH(B28,'SKRETTING PRECRIA'!$C$2:$C$25),1))/100,"")} -> 0.096909129 | E28: =(B28/1000)*$B$2*$E$2*D28 -> 358.01157 | F28: =E28/25 -> 14.320463 | G28: =E28*0.6/4 -> 53.701735 | H28: =E28*0.4 -> 143.20463 | I28: =E28/4 -> 89.502892
A29: 26 | B29: =B28*(1+$D$2) -> 2.4314537 | C29: =C28-0.01 -> 0.13 | D29: {=IFERROR((LOOKUP(B29,'SKRETTING PRECRIA'!$C$2:$C$25,'SKRETTING PRECRIA'!$G$2:$G$34)-((B29-INDEX('SKRETTING PRECRIA'!$C$2:$C$25,MATCH(B29,'SKRETTING PRECRIA'!$C$2:$C$25),1))/INDEX('SKRETTING PRECRIA'!$E$2:$E$25,MATCH(B29,'SKRETTING PRECRIA'!$C$2:$C$25),1))*INDEX('SKRETTING PRECRIA'!$H$2:$H$25,MATCH(B29,'SKRETTING PRECRIA'!$C$2:$C$25),1))/100,"")} -> 0.064112777 | E29: =(B29/1000)*$B$2*$E$2*D29 -> 305.53901 | F29: =E29/25 -> 12.22156 | G29: =E29*0.6/4 -> 45.830851 | H29: =E29*0.4 -> 122.2156 | I29: =E29/4 -> 76.384752
A30: 27 | B30: =B29*(1+$D$2) -> 3.1365753 | C30: =C29-0.01 -> 0.12 | D30: {=IFERROR((LOOKUP(B30,'SKRETTING PRECRIA'!$C$2:$C$25,'SKRETTING PRECRIA'!$G$2:$G$34)-((B30-INDEX('SKRETTING PRECRIA'!$C$2:$C$25,MATCH(B30,'SKRETTING PRECRIA'!$C$2:$C$25),1))/INDEX('SKRETTING PRECRIA'!$E$2:$E$25,MATCH(B30,'SKRETTING PRECRIA'!$C$2:$C$25),1))*INDEX('SKRETTING PRECRIA'!$H$2:$H$25,MATCH(B30,'SKRETTING PRECRIA'!$C$2:$C$25),1))/100,"")} -> 0.021805482 | E30: =(B30/1000)*$B$2*$E$2*D30 -> 134.05329 | F30: =E30/25 -> 5.3621316 | G30: =E30*0.6/4 -> 20.107994 | H30: =E30*0.4 -> 53.621316 | I30: =E30/4 -> 33.513323
A31: 28 | B31: =B30*(1+$D$2) -> 4.0461821 | D31: {=IFERROR((LOOKUP(B31,'SKRETTING PRECRIA'!$C$2:$C$25,'SKRETTING PRECRIA'!$G$2:$G$34)-((B31-INDEX('SKRETTING PRECRIA'!$C$2:$C$25,MATCH(B31,'SKRETTING PRECRIA'!$C$2:$C$25),1))/INDEX('SKRETTING PRECRIA'!$E$2:$E$25,MATCH(B31,'SKRETTING PRECRIA'!$C$2:$C$25),1))*INDEX('SKRETTING PRECRIA'!$H$2:$H$25,MATCH(B31,'SKRETTING PRECRIA'!$C$2:$C$25),1))/100,"")} -> -0.032770928 | E31: =(B31/1000)*$B$2*$E$2*D31 -> -259.8904 | F31: =E31/25 -> -10.395616 | G31: =E31*0.6/4 -> -38.98356 | H31: =E31*0.4 -> -103.95616 | I31: =E31/4 -> -64.972601
A32: 29 | B32: =B31*(1+$D$2) -> 5.219575 | D32: {=IFERROR((LOOKUP(B32,'SKRETTING PRECRIA'!$C$2:$C$25,'SKRETTING PRECRIA'!$G$2:$G$34)-((B32-INDEX('SKRETTING PRECRIA'!$C$2:$C$25,MATCH(B32,'SKRETTING PRECRIA'!$C$2:$C$25),1))/INDEX('SKRETTING PRECRIA'!$E$2:$E$25,MATCH(B32,'SKRETTING PRECRIA'!$C$2:$C$25),1))*INDEX('SKRETTING PRECRIA'!$H$2:$H$25,MATCH(B32,'SKRETTING PRECRIA'!$C$2:$C$25),1))/100,"")} -> -0.1031745 | E32: =(B32/1000)*$B$2*$E$2*D32 -> -1055.513 | F32: =E32/25 -> -42.220519 | G32: =E32*0.6/4 -> -158.32694 | H32: =E32*0.4 -> -422.20519 | I32: =E32/4 -> -263.87824
A33: 30 | B33: =B32*(1+$D$2) -> 6.7332517 | D33: {=IFERROR((LOOKUP(B33,'SKRETTING PRECRIA'!$C$2:$C$25,'SKRETTING PRECRIA'!$G$2:$G$34)-((B33-INDEX('SKRETTING PRECRIA'!$C$2:$C$25,MATCH(B33,'SKRETTING PRECRIA'!$C$2:$C$25),1))/INDEX('SKRETTING PRECRIA'!$E$2:$E$25,MATCH(B33,'SKRETTING PRECRIA'!$C$2:$C$25),1))*INDEX('SKRETTING PRECRIA'!$H$2:$H$25,MATCH(B33,'SKRETTING PRECRIA'!$C$2:$C$25),1))/100,"")} -> -0.1939951 | E33: =(B33/1000)*$B$2*$E$2*D33 -> -2560.187 | F33: =E33/25 -> -102.40748 | G33: =E33*0.6/4 -> -384.02805 | H33: =E33*0.4 -> -1024.0748 | I33: =E33/4 -> -640.04674

Sheet SEMANA CAMAGUI
A1: PISC | B1: HA | C1: SIEMBRA ID # | D1: DENSIDAD SIEMBRA | E1: DIAS | F1: PESO ACTUAL | G1: CREC. (g) | H1: ULTIMO TOPE (Kg) | I1: CONSUMO SEMANA (Kg) | J1: F.C. SEM. PROYEC. | K1: NOMBRE BALANCEAD. | L1: BALAN. TOT. (Kg) | M1: F.C. TOT. PROY. | N1: SOBREV. TOPE % | O1: SOBREV. PROY % | P1: DENSIDAD PROYECT. | Q1: CREC PROY (g) | R1: PESO OBJ (g) | S1: NUEVO TOPE (Kg) | T1: INCREMENT. DIARIO (Kg) | U1: RALEOS (Kg) | V1: PESCA PROY. (Kg) | W1: PESCA PROY. (Lb)
